WARNING 2025-05-14 14:44:26,934 log Bad Request: /admin_web/login/
WARNING 2025-05-14 14:44:26,934 basehttp "POST /admin_web/login/ HTTP/1.1" 400 54
WARNING 2025-05-14 14:44:34,051 log Bad Request: /admin_web/login/
WARNING 2025-05-14 14:44:34,052 basehttp "POST /admin_web/login/ HTTP/1.1" 400 54
WARNING 2025-05-14 15:15:42,778 log Bad Request: /admin_web/login/
WARNING 2025-05-14 15:15:42,779 basehttp "POST /admin_web/login/ HTTP/1.1" 400 54
WARNING 2025-05-14 15:40:42,386 log Bad Request: /admin_web/login/
WARNING 2025-05-14 15:40:42,387 basehttp "POST /admin_web/login/ HTTP/1.1" 400 54
ERROR 2025-05-14 15:44:36,952 log Internal Server Error: /admin_web/login/captcha/
Traceback (most recent call last):
  File "C:\Users\Spero\AppData\Roaming\Python\Python312\site-packages\django\db\backends\base\base.py", line 279, in ensure_connection
    self.connect()
  File "C:\Users\Spero\AppData\Roaming\Python\Python312\site-packages\django\utils\asyncio.py", line 26, in inner
    return func(*args, **kwargs)
           ^^^^^^^^^^^^^^^^^^^^^
  File "C:\Users\Spero\AppData\Roaming\Python\Python312\site-packages\django\db\backends\base\base.py", line 256, in connect
    self.connection = self.get_new_connection(conn_params)
                      ^^^^^^^^^^^^^^^^^^^^^^^^^^^^^^^^^^^^
  File "C:\Users\Spero\AppData\Roaming\Python\Python312\site-packages\django\utils\asyncio.py", line 26, in inner
    return func(*args, **kwargs)
           ^^^^^^^^^^^^^^^^^^^^^
  File "C:\Users\Spero\AppData\Roaming\Python\Python312\site-packages\django\db\backends\postgresql\base.py", line 332, in get_new_connection
    connection = self.Database.connect(**conn_params)
                 ^^^^^^^^^^^^^^^^^^^^^^^^^^^^^^^^^^^^
  File "C:\Users\Spero\AppData\Roaming\Python\Python312\site-packages\psycopg2\__init__.py", line 122, in connect
    conn = _connect(dsn, connection_factory=connection_factory, **kwasync)
           ^^^^^^^^^^^^^^^^^^^^^^^^^^^^^^^^^^^^^^^^^^^^^^^^^^^^^^^^^^^^^^^
psycopg2.OperationalError: connection to server at "192.168.1.116", port 5432 failed: No route to host (0x00002751/10065)
	Is the server running on that host and accepting TCP/IP connections?


The above exception was the direct cause of the following exception:

Traceback (most recent call last):
  File "C:\Users\Spero\AppData\Roaming\Python\Python312\site-packages\django\core\handlers\exception.py", line 55, in inner
    response = get_response(request)
               ^^^^^^^^^^^^^^^^^^^^^
  File "C:\Users\Spero\AppData\Roaming\Python\Python312\site-packages\django\core\handlers\base.py", line 197, in _get_response
    response = wrapped_callback(request, *callback_args, **callback_kwargs)
               ^^^^^^^^^^^^^^^^^^^^^^^^^^^^^^^^^^^^^^^^^^^^^^^^^^^^^^^^^^^^
  File "C:\Users\Spero\AppData\Roaming\Python\Python312\site-packages\django\views\decorators\csrf.py", line 65, in _view_wrapper
    return view_func(request, *args, **kwargs)
           ^^^^^^^^^^^^^^^^^^^^^^^^^^^^^^^^^^^
  File "C:\Users\Spero\AppData\Roaming\Python\Python312\site-packages\django\views\generic\base.py", line 104, in view
    return self.dispatch(request, *args, **kwargs)
           ^^^^^^^^^^^^^^^^^^^^^^^^^^^^^^^^^^^^^^^
  File "C:\Users\Spero\AppData\Roaming\Python\Python312\site-packages\rest_framework\views.py", line 515, in dispatch
    response = self.handle_exception(exc)
               ^^^^^^^^^^^^^^^^^^^^^^^^^^
  File "C:\Users\Spero\AppData\Roaming\Python\Python312\site-packages\rest_framework\views.py", line 475, in handle_exception
    self.raise_uncaught_exception(exc)
  File "C:\Users\Spero\AppData\Roaming\Python\Python312\site-packages\rest_framework\views.py", line 486, in raise_uncaught_exception
    raise exc
  File "C:\Users\Spero\AppData\Roaming\Python\Python312\site-packages\rest_framework\views.py", line 512, in dispatch
    response = handler(request, *args, **kwargs)
               ^^^^^^^^^^^^^^^^^^^^^^^^^^^^^^^^^
  File "C:\Spero\Spero-DMS\DMS_goa\admin_web\views.py", line 256, in get
    new_captcha = CaptchaStore.generate_key()
                  ^^^^^^^^^^^^^^^^^^^^^^^^^^^
  File "C:\Users\Spero\AppData\Roaming\Python\Python312\site-packages\captcha\models.py", line 60, in generate_key
    store = cls.objects.create(challenge=challenge, response=response)
            ^^^^^^^^^^^^^^^^^^^^^^^^^^^^^^^^^^^^^^^^^^^^^^^^^^^^^^^^^^
  File "C:\Users\Spero\AppData\Roaming\Python\Python312\site-packages\django\db\models\manager.py", line 87, in manager_method
    return getattr(self.get_queryset(), name)(*args, **kwargs)
           ^^^^^^^^^^^^^^^^^^^^^^^^^^^^^^^^^^^^^^^^^^^^^^^^^^^
  File "C:\Users\Spero\AppData\Roaming\Python\Python312\site-packages\django\db\models\query.py", line 663, in create
    obj.save(force_insert=True, using=self.db)
  File "C:\Users\Spero\AppData\Roaming\Python\Python312\site-packages\captcha\models.py", line 47, in save
    super().save(*args, **kwargs)
  File "C:\Users\Spero\AppData\Roaming\Python\Python312\site-packages\django\db\models\base.py", line 902, in save
    self.save_base(
  File "C:\Users\Spero\AppData\Roaming\Python\Python312\site-packages\django\db\models\base.py", line 1008, in save_base
    updated = self._save_table(
              ^^^^^^^^^^^^^^^^^
  File "C:\Users\Spero\AppData\Roaming\Python\Python312\site-packages\django\db\models\base.py", line 1169, in _save_table
    results = self._do_insert(
              ^^^^^^^^^^^^^^^^
  File "C:\Users\Spero\AppData\Roaming\Python\Python312\site-packages\django\db\models\base.py", line 1210, in _do_insert
    return manager._insert(
           ^^^^^^^^^^^^^^^^
  File "C:\Users\Spero\AppData\Roaming\Python\Python312\site-packages\django\db\models\manager.py", line 87, in manager_method
    return getattr(self.get_queryset(), name)(*args, **kwargs)
           ^^^^^^^^^^^^^^^^^^^^^^^^^^^^^^^^^^^^^^^^^^^^^^^^^^^
  File "C:\Users\Spero\AppData\Roaming\Python\Python312\site-packages\django\db\models\query.py", line 1864, in _insert
    return query.get_compiler(using=using).execute_sql(returning_fields)
           ^^^^^^^^^^^^^^^^^^^^^^^^^^^^^^^^^^^^^^^^^^^^^^^^^^^^^^^^^^^^^
  File "C:\Users\Spero\AppData\Roaming\Python\Python312\site-packages\django\db\models\sql\compiler.py", line 1880, in execute_sql
    with self.connection.cursor() as cursor:
         ^^^^^^^^^^^^^^^^^^^^^^^^
  File "C:\Users\Spero\AppData\Roaming\Python\Python312\site-packages\django\utils\asyncio.py", line 26, in inner
    return func(*args, **kwargs)
           ^^^^^^^^^^^^^^^^^^^^^
  File "C:\Users\Spero\AppData\Roaming\Python\Python312\site-packages\django\db\backends\base\base.py", line 320, in cursor
    return self._cursor()
           ^^^^^^^^^^^^^^
  File "C:\Users\Spero\AppData\Roaming\Python\Python312\site-packages\django\db\backends\base\base.py", line 296, in _cursor
    self.ensure_connection()
  File "C:\Users\Spero\AppData\Roaming\Python\Python312\site-packages\django\utils\asyncio.py", line 26, in inner
    return func(*args, **kwargs)
           ^^^^^^^^^^^^^^^^^^^^^
  File "C:\Users\Spero\AppData\Roaming\Python\Python312\site-packages\django\db\backends\base\base.py", line 278, in ensure_connection
    with self.wrap_database_errors:
         ^^^^^^^^^^^^^^^^^^^^^^^^^
  File "C:\Users\Spero\AppData\Roaming\Python\Python312\site-packages\django\db\utils.py", line 91, in __exit__
    raise dj_exc_value.with_traceback(traceback) from exc_value
  File "C:\Users\Spero\AppData\Roaming\Python\Python312\site-packages\django\db\backends\base\base.py", line 279, in ensure_connection
    self.connect()
  File "C:\Users\Spero\AppData\Roaming\Python\Python312\site-packages\django\utils\asyncio.py", line 26, in inner
    return func(*args, **kwargs)
           ^^^^^^^^^^^^^^^^^^^^^
  File "C:\Users\Spero\AppData\Roaming\Python\Python312\site-packages\django\db\backends\base\base.py", line 256, in connect
    self.connection = self.get_new_connection(conn_params)
                      ^^^^^^^^^^^^^^^^^^^^^^^^^^^^^^^^^^^^
  File "C:\Users\Spero\AppData\Roaming\Python\Python312\site-packages\django\utils\asyncio.py", line 26, in inner
    return func(*args, **kwargs)
           ^^^^^^^^^^^^^^^^^^^^^
  File "C:\Users\Spero\AppData\Roaming\Python\Python312\site-packages\django\db\backends\postgresql\base.py", line 332, in get_new_connection
    connection = self.Database.connect(**conn_params)
                 ^^^^^^^^^^^^^^^^^^^^^^^^^^^^^^^^^^^^
  File "C:\Users\Spero\AppData\Roaming\Python\Python312\site-packages\psycopg2\__init__.py", line 122, in connect
    conn = _connect(dsn, connection_factory=connection_factory, **kwasync)
           ^^^^^^^^^^^^^^^^^^^^^^^^^^^^^^^^^^^^^^^^^^^^^^^^^^^^^^^^^^^^^^^
django.db.utils.OperationalError: connection to server at "192.168.1.116", port 5432 failed: No route to host (0x00002751/10065)
	Is the server running on that host and accepting TCP/IP connections?

ERROR 2025-05-14 15:44:36,970 log Internal Server Error: /admin_web/login/captcha/
Traceback (most recent call last):
  File "C:\Users\Spero\AppData\Roaming\Python\Python312\site-packages\django\db\backends\base\base.py", line 279, in ensure_connection
    self.connect()
  File "C:\Users\Spero\AppData\Roaming\Python\Python312\site-packages\django\utils\asyncio.py", line 26, in inner
    return func(*args, **kwargs)
           ^^^^^^^^^^^^^^^^^^^^^
  File "C:\Users\Spero\AppData\Roaming\Python\Python312\site-packages\django\db\backends\base\base.py", line 256, in connect
    self.connection = self.get_new_connection(conn_params)
                      ^^^^^^^^^^^^^^^^^^^^^^^^^^^^^^^^^^^^
  File "C:\Users\Spero\AppData\Roaming\Python\Python312\site-packages\django\utils\asyncio.py", line 26, in inner
    return func(*args, **kwargs)
           ^^^^^^^^^^^^^^^^^^^^^
  File "C:\Users\Spero\AppData\Roaming\Python\Python312\site-packages\django\db\backends\postgresql\base.py", line 332, in get_new_connection
    connection = self.Database.connect(**conn_params)
                 ^^^^^^^^^^^^^^^^^^^^^^^^^^^^^^^^^^^^
  File "C:\Users\Spero\AppData\Roaming\Python\Python312\site-packages\psycopg2\__init__.py", line 122, in connect
    conn = _connect(dsn, connection_factory=connection_factory, **kwasync)
           ^^^^^^^^^^^^^^^^^^^^^^^^^^^^^^^^^^^^^^^^^^^^^^^^^^^^^^^^^^^^^^^
psycopg2.OperationalError: connection to server at "192.168.1.116", port 5432 failed: No route to host (0x00002751/10065)
	Is the server running on that host and accepting TCP/IP connections?


The above exception was the direct cause of the following exception:

Traceback (most recent call last):
  File "C:\Users\Spero\AppData\Roaming\Python\Python312\site-packages\django\core\handlers\exception.py", line 55, in inner
    response = get_response(request)
               ^^^^^^^^^^^^^^^^^^^^^
  File "C:\Users\Spero\AppData\Roaming\Python\Python312\site-packages\django\core\handlers\base.py", line 197, in _get_response
    response = wrapped_callback(request, *callback_args, **callback_kwargs)
               ^^^^^^^^^^^^^^^^^^^^^^^^^^^^^^^^^^^^^^^^^^^^^^^^^^^^^^^^^^^^
  File "C:\Users\Spero\AppData\Roaming\Python\Python312\site-packages\django\views\decorators\csrf.py", line 65, in _view_wrapper
    return view_func(request, *args, **kwargs)
           ^^^^^^^^^^^^^^^^^^^^^^^^^^^^^^^^^^^
  File "C:\Users\Spero\AppData\Roaming\Python\Python312\site-packages\django\views\generic\base.py", line 104, in view
    return self.dispatch(request, *args, **kwargs)
           ^^^^^^^^^^^^^^^^^^^^^^^^^^^^^^^^^^^^^^^
  File "C:\Users\Spero\AppData\Roaming\Python\Python312\site-packages\rest_framework\views.py", line 515, in dispatch
    response = self.handle_exception(exc)
               ^^^^^^^^^^^^^^^^^^^^^^^^^^
  File "C:\Users\Spero\AppData\Roaming\Python\Python312\site-packages\rest_framework\views.py", line 475, in handle_exception
    self.raise_uncaught_exception(exc)
  File "C:\Users\Spero\AppData\Roaming\Python\Python312\site-packages\rest_framework\views.py", line 486, in raise_uncaught_exception
    raise exc
  File "C:\Users\Spero\AppData\Roaming\Python\Python312\site-packages\rest_framework\views.py", line 512, in dispatch
    response = handler(request, *args, **kwargs)
               ^^^^^^^^^^^^^^^^^^^^^^^^^^^^^^^^^
  File "C:\Spero\Spero-DMS\DMS_goa\admin_web\views.py", line 256, in get
    new_captcha = CaptchaStore.generate_key()
                  ^^^^^^^^^^^^^^^^^^^^^^^^^^^
  File "C:\Users\Spero\AppData\Roaming\Python\Python312\site-packages\captcha\models.py", line 60, in generate_key
    store = cls.objects.create(challenge=challenge, response=response)
            ^^^^^^^^^^^^^^^^^^^^^^^^^^^^^^^^^^^^^^^^^^^^^^^^^^^^^^^^^^
  File "C:\Users\Spero\AppData\Roaming\Python\Python312\site-packages\django\db\models\manager.py", line 87, in manager_method
    return getattr(self.get_queryset(), name)(*args, **kwargs)
           ^^^^^^^^^^^^^^^^^^^^^^^^^^^^^^^^^^^^^^^^^^^^^^^^^^^
  File "C:\Users\Spero\AppData\Roaming\Python\Python312\site-packages\django\db\models\query.py", line 663, in create
    obj.save(force_insert=True, using=self.db)
  File "C:\Users\Spero\AppData\Roaming\Python\Python312\site-packages\captcha\models.py", line 47, in save
    super().save(*args, **kwargs)
  File "C:\Users\Spero\AppData\Roaming\Python\Python312\site-packages\django\db\models\base.py", line 902, in save
    self.save_base(
  File "C:\Users\Spero\AppData\Roaming\Python\Python312\site-packages\django\db\models\base.py", line 1008, in save_base
    updated = self._save_table(
              ^^^^^^^^^^^^^^^^^
  File "C:\Users\Spero\AppData\Roaming\Python\Python312\site-packages\django\db\models\base.py", line 1169, in _save_table
    results = self._do_insert(
              ^^^^^^^^^^^^^^^^
  File "C:\Users\Spero\AppData\Roaming\Python\Python312\site-packages\django\db\models\base.py", line 1210, in _do_insert
    return manager._insert(
           ^^^^^^^^^^^^^^^^
  File "C:\Users\Spero\AppData\Roaming\Python\Python312\site-packages\django\db\models\manager.py", line 87, in manager_method
    return getattr(self.get_queryset(), name)(*args, **kwargs)
           ^^^^^^^^^^^^^^^^^^^^^^^^^^^^^^^^^^^^^^^^^^^^^^^^^^^
  File "C:\Users\Spero\AppData\Roaming\Python\Python312\site-packages\django\db\models\query.py", line 1864, in _insert
    return query.get_compiler(using=using).execute_sql(returning_fields)
           ^^^^^^^^^^^^^^^^^^^^^^^^^^^^^^^^^^^^^^^^^^^^^^^^^^^^^^^^^^^^^
  File "C:\Users\Spero\AppData\Roaming\Python\Python312\site-packages\django\db\models\sql\compiler.py", line 1880, in execute_sql
    with self.connection.cursor() as cursor:
         ^^^^^^^^^^^^^^^^^^^^^^^^
  File "C:\Users\Spero\AppData\Roaming\Python\Python312\site-packages\django\utils\asyncio.py", line 26, in inner
    return func(*args, **kwargs)
           ^^^^^^^^^^^^^^^^^^^^^
  File "C:\Users\Spero\AppData\Roaming\Python\Python312\site-packages\django\db\backends\base\base.py", line 320, in cursor
    return self._cursor()
           ^^^^^^^^^^^^^^
  File "C:\Users\Spero\AppData\Roaming\Python\Python312\site-packages\django\db\backends\base\base.py", line 296, in _cursor
    self.ensure_connection()
  File "C:\Users\Spero\AppData\Roaming\Python\Python312\site-packages\django\utils\asyncio.py", line 26, in inner
    return func(*args, **kwargs)
           ^^^^^^^^^^^^^^^^^^^^^
  File "C:\Users\Spero\AppData\Roaming\Python\Python312\site-packages\django\db\backends\base\base.py", line 278, in ensure_connection
    with self.wrap_database_errors:
         ^^^^^^^^^^^^^^^^^^^^^^^^^
  File "C:\Users\Spero\AppData\Roaming\Python\Python312\site-packages\django\db\utils.py", line 91, in __exit__
    raise dj_exc_value.with_traceback(traceback) from exc_value
  File "C:\Users\Spero\AppData\Roaming\Python\Python312\site-packages\django\db\backends\base\base.py", line 279, in ensure_connection
    self.connect()
  File "C:\Users\Spero\AppData\Roaming\Python\Python312\site-packages\django\utils\asyncio.py", line 26, in inner
    return func(*args, **kwargs)
           ^^^^^^^^^^^^^^^^^^^^^
  File "C:\Users\Spero\AppData\Roaming\Python\Python312\site-packages\django\db\backends\base\base.py", line 256, in connect
    self.connection = self.get_new_connection(conn_params)
                      ^^^^^^^^^^^^^^^^^^^^^^^^^^^^^^^^^^^^
  File "C:\Users\Spero\AppData\Roaming\Python\Python312\site-packages\django\utils\asyncio.py", line 26, in inner
    return func(*args, **kwargs)
           ^^^^^^^^^^^^^^^^^^^^^
  File "C:\Users\Spero\AppData\Roaming\Python\Python312\site-packages\django\db\backends\postgresql\base.py", line 332, in get_new_connection
    connection = self.Database.connect(**conn_params)
                 ^^^^^^^^^^^^^^^^^^^^^^^^^^^^^^^^^^^^
  File "C:\Users\Spero\AppData\Roaming\Python\Python312\site-packages\psycopg2\__init__.py", line 122, in connect
    conn = _connect(dsn, connection_factory=connection_factory, **kwasync)
           ^^^^^^^^^^^^^^^^^^^^^^^^^^^^^^^^^^^^^^^^^^^^^^^^^^^^^^^^^^^^^^^
django.db.utils.OperationalError: connection to server at "192.168.1.116", port 5432 failed: No route to host (0x00002751/10065)
	Is the server running on that host and accepting TCP/IP connections?

ERROR 2025-05-14 15:44:36,981 basehttp "GET /admin_web/login/captcha/ HTTP/1.1" 500 229351
ERROR 2025-05-14 15:44:36,987 basehttp "GET /admin_web/login/captcha/ HTTP/1.1" 500 229232
ERROR 2025-05-14 16:03:56,631 log Internal Server Error: /admin_web/login/captcha/
Traceback (most recent call last):
  File "C:\Users\Spero\AppData\Roaming\Python\Python312\site-packages\django\db\backends\base\base.py", line 279, in ensure_connection
    self.connect()
  File "C:\Users\Spero\AppData\Roaming\Python\Python312\site-packages\django\utils\asyncio.py", line 26, in inner
    return func(*args, **kwargs)
           ^^^^^^^^^^^^^^^^^^^^^
  File "C:\Users\Spero\AppData\Roaming\Python\Python312\site-packages\django\db\backends\base\base.py", line 256, in connect
    self.connection = self.get_new_connection(conn_params)
                      ^^^^^^^^^^^^^^^^^^^^^^^^^^^^^^^^^^^^
  File "C:\Users\Spero\AppData\Roaming\Python\Python312\site-packages\django\utils\asyncio.py", line 26, in inner
    return func(*args, **kwargs)
           ^^^^^^^^^^^^^^^^^^^^^
  File "C:\Users\Spero\AppData\Roaming\Python\Python312\site-packages\django\db\backends\postgresql\base.py", line 332, in get_new_connection
    connection = self.Database.connect(**conn_params)
                 ^^^^^^^^^^^^^^^^^^^^^^^^^^^^^^^^^^^^
  File "C:\Users\Spero\AppData\Roaming\Python\Python312\site-packages\psycopg2\__init__.py", line 122, in connect
    conn = _connect(dsn, connection_factory=connection_factory, **kwasync)
           ^^^^^^^^^^^^^^^^^^^^^^^^^^^^^^^^^^^^^^^^^^^^^^^^^^^^^^^^^^^^^^^
psycopg2.OperationalError: connection to server at "192.168.1.116", port 5432 failed: No route to host (0x00002751/10065)
	Is the server running on that host and accepting TCP/IP connections?


The above exception was the direct cause of the following exception:

Traceback (most recent call last):
  File "C:\Users\Spero\AppData\Roaming\Python\Python312\site-packages\django\core\handlers\exception.py", line 55, in inner
    response = get_response(request)
               ^^^^^^^^^^^^^^^^^^^^^
  File "C:\Users\Spero\AppData\Roaming\Python\Python312\site-packages\django\core\handlers\base.py", line 197, in _get_response
    response = wrapped_callback(request, *callback_args, **callback_kwargs)
               ^^^^^^^^^^^^^^^^^^^^^^^^^^^^^^^^^^^^^^^^^^^^^^^^^^^^^^^^^^^^
  File "C:\Users\Spero\AppData\Roaming\Python\Python312\site-packages\django\views\decorators\csrf.py", line 65, in _view_wrapper
    return view_func(request, *args, **kwargs)
           ^^^^^^^^^^^^^^^^^^^^^^^^^^^^^^^^^^^
  File "C:\Users\Spero\AppData\Roaming\Python\Python312\site-packages\django\views\generic\base.py", line 104, in view
    return self.dispatch(request, *args, **kwargs)
           ^^^^^^^^^^^^^^^^^^^^^^^^^^^^^^^^^^^^^^^
  File "C:\Users\Spero\AppData\Roaming\Python\Python312\site-packages\rest_framework\views.py", line 515, in dispatch
    response = self.handle_exception(exc)
               ^^^^^^^^^^^^^^^^^^^^^^^^^^
  File "C:\Users\Spero\AppData\Roaming\Python\Python312\site-packages\rest_framework\views.py", line 475, in handle_exception
    self.raise_uncaught_exception(exc)
  File "C:\Users\Spero\AppData\Roaming\Python\Python312\site-packages\rest_framework\views.py", line 486, in raise_uncaught_exception
    raise exc
  File "C:\Users\Spero\AppData\Roaming\Python\Python312\site-packages\rest_framework\views.py", line 512, in dispatch
    response = handler(request, *args, **kwargs)
               ^^^^^^^^^^^^^^^^^^^^^^^^^^^^^^^^^
  File "C:\Spero\Spero-DMS\DMS_goa\admin_web\views.py", line 256, in get
    new_captcha = CaptchaStore.generate_key()
                  ^^^^^^^^^^^^^^^^^^^^^^^^^^^
  File "C:\Users\Spero\AppData\Roaming\Python\Python312\site-packages\captcha\models.py", line 60, in generate_key
    store = cls.objects.create(challenge=challenge, response=response)
            ^^^^^^^^^^^^^^^^^^^^^^^^^^^^^^^^^^^^^^^^^^^^^^^^^^^^^^^^^^
  File "C:\Users\Spero\AppData\Roaming\Python\Python312\site-packages\django\db\models\manager.py", line 87, in manager_method
    return getattr(self.get_queryset(), name)(*args, **kwargs)
           ^^^^^^^^^^^^^^^^^^^^^^^^^^^^^^^^^^^^^^^^^^^^^^^^^^^
  File "C:\Users\Spero\AppData\Roaming\Python\Python312\site-packages\django\db\models\query.py", line 663, in create
    obj.save(force_insert=True, using=self.db)
  File "C:\Users\Spero\AppData\Roaming\Python\Python312\site-packages\captcha\models.py", line 47, in save
    super().save(*args, **kwargs)
  File "C:\Users\Spero\AppData\Roaming\Python\Python312\site-packages\django\db\models\base.py", line 902, in save
    self.save_base(
  File "C:\Users\Spero\AppData\Roaming\Python\Python312\site-packages\django\db\models\base.py", line 1008, in save_base
    updated = self._save_table(
              ^^^^^^^^^^^^^^^^^
  File "C:\Users\Spero\AppData\Roaming\Python\Python312\site-packages\django\db\models\base.py", line 1169, in _save_table
    results = self._do_insert(
              ^^^^^^^^^^^^^^^^
  File "C:\Users\Spero\AppData\Roaming\Python\Python312\site-packages\django\db\models\base.py", line 1210, in _do_insert
    return manager._insert(
           ^^^^^^^^^^^^^^^^
  File "C:\Users\Spero\AppData\Roaming\Python\Python312\site-packages\django\db\models\manager.py", line 87, in manager_method
    return getattr(self.get_queryset(), name)(*args, **kwargs)
           ^^^^^^^^^^^^^^^^^^^^^^^^^^^^^^^^^^^^^^^^^^^^^^^^^^^
  File "C:\Users\Spero\AppData\Roaming\Python\Python312\site-packages\django\db\models\query.py", line 1864, in _insert
    return query.get_compiler(using=using).execute_sql(returning_fields)
           ^^^^^^^^^^^^^^^^^^^^^^^^^^^^^^^^^^^^^^^^^^^^^^^^^^^^^^^^^^^^^
  File "C:\Users\Spero\AppData\Roaming\Python\Python312\site-packages\django\db\models\sql\compiler.py", line 1880, in execute_sql
    with self.connection.cursor() as cursor:
         ^^^^^^^^^^^^^^^^^^^^^^^^
  File "C:\Users\Spero\AppData\Roaming\Python\Python312\site-packages\django\utils\asyncio.py", line 26, in inner
    return func(*args, **kwargs)
           ^^^^^^^^^^^^^^^^^^^^^
  File "C:\Users\Spero\AppData\Roaming\Python\Python312\site-packages\django\db\backends\base\base.py", line 320, in cursor
    return self._cursor()
           ^^^^^^^^^^^^^^
  File "C:\Users\Spero\AppData\Roaming\Python\Python312\site-packages\django\db\backends\base\base.py", line 296, in _cursor
    self.ensure_connection()
  File "C:\Users\Spero\AppData\Roaming\Python\Python312\site-packages\django\utils\asyncio.py", line 26, in inner
    return func(*args, **kwargs)
           ^^^^^^^^^^^^^^^^^^^^^
  File "C:\Users\Spero\AppData\Roaming\Python\Python312\site-packages\django\db\backends\base\base.py", line 278, in ensure_connection
    with self.wrap_database_errors:
         ^^^^^^^^^^^^^^^^^^^^^^^^^
  File "C:\Users\Spero\AppData\Roaming\Python\Python312\site-packages\django\db\utils.py", line 91, in __exit__
    raise dj_exc_value.with_traceback(traceback) from exc_value
  File "C:\Users\Spero\AppData\Roaming\Python\Python312\site-packages\django\db\backends\base\base.py", line 279, in ensure_connection
    self.connect()
  File "C:\Users\Spero\AppData\Roaming\Python\Python312\site-packages\django\utils\asyncio.py", line 26, in inner
    return func(*args, **kwargs)
           ^^^^^^^^^^^^^^^^^^^^^
  File "C:\Users\Spero\AppData\Roaming\Python\Python312\site-packages\django\db\backends\base\base.py", line 256, in connect
    self.connection = self.get_new_connection(conn_params)
                      ^^^^^^^^^^^^^^^^^^^^^^^^^^^^^^^^^^^^
  File "C:\Users\Spero\AppData\Roaming\Python\Python312\site-packages\django\utils\asyncio.py", line 26, in inner
    return func(*args, **kwargs)
           ^^^^^^^^^^^^^^^^^^^^^
  File "C:\Users\Spero\AppData\Roaming\Python\Python312\site-packages\django\db\backends\postgresql\base.py", line 332, in get_new_connection
    connection = self.Database.connect(**conn_params)
                 ^^^^^^^^^^^^^^^^^^^^^^^^^^^^^^^^^^^^
  File "C:\Users\Spero\AppData\Roaming\Python\Python312\site-packages\psycopg2\__init__.py", line 122, in connect
    conn = _connect(dsn, connection_factory=connection_factory, **kwasync)
           ^^^^^^^^^^^^^^^^^^^^^^^^^^^^^^^^^^^^^^^^^^^^^^^^^^^^^^^^^^^^^^^
django.db.utils.OperationalError: connection to server at "192.168.1.116", port 5432 failed: No route to host (0x00002751/10065)
	Is the server running on that host and accepting TCP/IP connections?

ERROR 2025-05-14 16:03:56,639 basehttp "GET /admin_web/login/captcha/ HTTP/1.1" 500 229232
ERROR 2025-05-14 16:03:56,759 log Internal Server Error: /admin_web/login/captcha/
Traceback (most recent call last):
  File "C:\Users\Spero\AppData\Roaming\Python\Python312\site-packages\django\db\backends\base\base.py", line 279, in ensure_connection
    self.connect()
  File "C:\Users\Spero\AppData\Roaming\Python\Python312\site-packages\django\utils\asyncio.py", line 26, in inner
    return func(*args, **kwargs)
           ^^^^^^^^^^^^^^^^^^^^^
  File "C:\Users\Spero\AppData\Roaming\Python\Python312\site-packages\django\db\backends\base\base.py", line 256, in connect
    self.connection = self.get_new_connection(conn_params)
                      ^^^^^^^^^^^^^^^^^^^^^^^^^^^^^^^^^^^^
  File "C:\Users\Spero\AppData\Roaming\Python\Python312\site-packages\django\utils\asyncio.py", line 26, in inner
    return func(*args, **kwargs)
           ^^^^^^^^^^^^^^^^^^^^^
  File "C:\Users\Spero\AppData\Roaming\Python\Python312\site-packages\django\db\backends\postgresql\base.py", line 332, in get_new_connection
    connection = self.Database.connect(**conn_params)
                 ^^^^^^^^^^^^^^^^^^^^^^^^^^^^^^^^^^^^
  File "C:\Users\Spero\AppData\Roaming\Python\Python312\site-packages\psycopg2\__init__.py", line 122, in connect
    conn = _connect(dsn, connection_factory=connection_factory, **kwasync)
           ^^^^^^^^^^^^^^^^^^^^^^^^^^^^^^^^^^^^^^^^^^^^^^^^^^^^^^^^^^^^^^^
psycopg2.OperationalError: connection to server at "192.168.1.116", port 5432 failed: No route to host (0x00002751/10065)
	Is the server running on that host and accepting TCP/IP connections?


The above exception was the direct cause of the following exception:

Traceback (most recent call last):
  File "C:\Users\Spero\AppData\Roaming\Python\Python312\site-packages\django\core\handlers\exception.py", line 55, in inner
    response = get_response(request)
               ^^^^^^^^^^^^^^^^^^^^^
  File "C:\Users\Spero\AppData\Roaming\Python\Python312\site-packages\django\core\handlers\base.py", line 197, in _get_response
    response = wrapped_callback(request, *callback_args, **callback_kwargs)
               ^^^^^^^^^^^^^^^^^^^^^^^^^^^^^^^^^^^^^^^^^^^^^^^^^^^^^^^^^^^^
  File "C:\Users\Spero\AppData\Roaming\Python\Python312\site-packages\django\views\decorators\csrf.py", line 65, in _view_wrapper
    return view_func(request, *args, **kwargs)
           ^^^^^^^^^^^^^^^^^^^^^^^^^^^^^^^^^^^
  File "C:\Users\Spero\AppData\Roaming\Python\Python312\site-packages\django\views\generic\base.py", line 104, in view
    return self.dispatch(request, *args, **kwargs)
           ^^^^^^^^^^^^^^^^^^^^^^^^^^^^^^^^^^^^^^^
  File "C:\Users\Spero\AppData\Roaming\Python\Python312\site-packages\rest_framework\views.py", line 515, in dispatch
    response = self.handle_exception(exc)
               ^^^^^^^^^^^^^^^^^^^^^^^^^^
  File "C:\Users\Spero\AppData\Roaming\Python\Python312\site-packages\rest_framework\views.py", line 475, in handle_exception
    self.raise_uncaught_exception(exc)
  File "C:\Users\Spero\AppData\Roaming\Python\Python312\site-packages\rest_framework\views.py", line 486, in raise_uncaught_exception
    raise exc
  File "C:\Users\Spero\AppData\Roaming\Python\Python312\site-packages\rest_framework\views.py", line 512, in dispatch
    response = handler(request, *args, **kwargs)
               ^^^^^^^^^^^^^^^^^^^^^^^^^^^^^^^^^
  File "C:\Spero\Spero-DMS\DMS_goa\admin_web\views.py", line 256, in get
    new_captcha = CaptchaStore.generate_key()
                  ^^^^^^^^^^^^^^^^^^^^^^^^^^^
  File "C:\Users\Spero\AppData\Roaming\Python\Python312\site-packages\captcha\models.py", line 60, in generate_key
    store = cls.objects.create(challenge=challenge, response=response)
            ^^^^^^^^^^^^^^^^^^^^^^^^^^^^^^^^^^^^^^^^^^^^^^^^^^^^^^^^^^
  File "C:\Users\Spero\AppData\Roaming\Python\Python312\site-packages\django\db\models\manager.py", line 87, in manager_method
    return getattr(self.get_queryset(), name)(*args, **kwargs)
           ^^^^^^^^^^^^^^^^^^^^^^^^^^^^^^^^^^^^^^^^^^^^^^^^^^^
  File "C:\Users\Spero\AppData\Roaming\Python\Python312\site-packages\django\db\models\query.py", line 663, in create
    obj.save(force_insert=True, using=self.db)
  File "C:\Users\Spero\AppData\Roaming\Python\Python312\site-packages\captcha\models.py", line 47, in save
    super().save(*args, **kwargs)
  File "C:\Users\Spero\AppData\Roaming\Python\Python312\site-packages\django\db\models\base.py", line 902, in save
    self.save_base(
  File "C:\Users\Spero\AppData\Roaming\Python\Python312\site-packages\django\db\models\base.py", line 1008, in save_base
    updated = self._save_table(
              ^^^^^^^^^^^^^^^^^
  File "C:\Users\Spero\AppData\Roaming\Python\Python312\site-packages\django\db\models\base.py", line 1169, in _save_table
    results = self._do_insert(
              ^^^^^^^^^^^^^^^^
  File "C:\Users\Spero\AppData\Roaming\Python\Python312\site-packages\django\db\models\base.py", line 1210, in _do_insert
    return manager._insert(
           ^^^^^^^^^^^^^^^^
  File "C:\Users\Spero\AppData\Roaming\Python\Python312\site-packages\django\db\models\manager.py", line 87, in manager_method
    return getattr(self.get_queryset(), name)(*args, **kwargs)
           ^^^^^^^^^^^^^^^^^^^^^^^^^^^^^^^^^^^^^^^^^^^^^^^^^^^
  File "C:\Users\Spero\AppData\Roaming\Python\Python312\site-packages\django\db\models\query.py", line 1864, in _insert
    return query.get_compiler(using=using).execute_sql(returning_fields)
           ^^^^^^^^^^^^^^^^^^^^^^^^^^^^^^^^^^^^^^^^^^^^^^^^^^^^^^^^^^^^^
  File "C:\Users\Spero\AppData\Roaming\Python\Python312\site-packages\django\db\models\sql\compiler.py", line 1880, in execute_sql
    with self.connection.cursor() as cursor:
         ^^^^^^^^^^^^^^^^^^^^^^^^
  File "C:\Users\Spero\AppData\Roaming\Python\Python312\site-packages\django\utils\asyncio.py", line 26, in inner
    return func(*args, **kwargs)
           ^^^^^^^^^^^^^^^^^^^^^
  File "C:\Users\Spero\AppData\Roaming\Python\Python312\site-packages\django\db\backends\base\base.py", line 320, in cursor
    return self._cursor()
           ^^^^^^^^^^^^^^
  File "C:\Users\Spero\AppData\Roaming\Python\Python312\site-packages\django\db\backends\base\base.py", line 296, in _cursor
    self.ensure_connection()
  File "C:\Users\Spero\AppData\Roaming\Python\Python312\site-packages\django\utils\asyncio.py", line 26, in inner
    return func(*args, **kwargs)
           ^^^^^^^^^^^^^^^^^^^^^
  File "C:\Users\Spero\AppData\Roaming\Python\Python312\site-packages\django\db\backends\base\base.py", line 278, in ensure_connection
    with self.wrap_database_errors:
         ^^^^^^^^^^^^^^^^^^^^^^^^^
  File "C:\Users\Spero\AppData\Roaming\Python\Python312\site-packages\django\db\utils.py", line 91, in __exit__
    raise dj_exc_value.with_traceback(traceback) from exc_value
  File "C:\Users\Spero\AppData\Roaming\Python\Python312\site-packages\django\db\backends\base\base.py", line 279, in ensure_connection
    self.connect()
  File "C:\Users\Spero\AppData\Roaming\Python\Python312\site-packages\django\utils\asyncio.py", line 26, in inner
    return func(*args, **kwargs)
           ^^^^^^^^^^^^^^^^^^^^^
  File "C:\Users\Spero\AppData\Roaming\Python\Python312\site-packages\django\db\backends\base\base.py", line 256, in connect
    self.connection = self.get_new_connection(conn_params)
                      ^^^^^^^^^^^^^^^^^^^^^^^^^^^^^^^^^^^^
  File "C:\Users\Spero\AppData\Roaming\Python\Python312\site-packages\django\utils\asyncio.py", line 26, in inner
    return func(*args, **kwargs)
           ^^^^^^^^^^^^^^^^^^^^^
  File "C:\Users\Spero\AppData\Roaming\Python\Python312\site-packages\django\db\backends\postgresql\base.py", line 332, in get_new_connection
    connection = self.Database.connect(**conn_params)
                 ^^^^^^^^^^^^^^^^^^^^^^^^^^^^^^^^^^^^
  File "C:\Users\Spero\AppData\Roaming\Python\Python312\site-packages\psycopg2\__init__.py", line 122, in connect
    conn = _connect(dsn, connection_factory=connection_factory, **kwasync)
           ^^^^^^^^^^^^^^^^^^^^^^^^^^^^^^^^^^^^^^^^^^^^^^^^^^^^^^^^^^^^^^^
django.db.utils.OperationalError: connection to server at "192.168.1.116", port 5432 failed: No route to host (0x00002751/10065)
	Is the server running on that host and accepting TCP/IP connections?

ERROR 2025-05-14 16:03:56,768 basehttp "GET /admin_web/login/captcha/ HTTP/1.1" 500 229232
ERROR 2025-05-14 16:04:05,361 log Internal Server Error: /admin_web/login/captcha/
Traceback (most recent call last):
  File "C:\Users\Spero\AppData\Roaming\Python\Python312\site-packages\django\db\backends\base\base.py", line 279, in ensure_connection
    self.connect()
  File "C:\Users\Spero\AppData\Roaming\Python\Python312\site-packages\django\utils\asyncio.py", line 26, in inner
    return func(*args, **kwargs)
           ^^^^^^^^^^^^^^^^^^^^^
  File "C:\Users\Spero\AppData\Roaming\Python\Python312\site-packages\django\db\backends\base\base.py", line 256, in connect
    self.connection = self.get_new_connection(conn_params)
                      ^^^^^^^^^^^^^^^^^^^^^^^^^^^^^^^^^^^^
  File "C:\Users\Spero\AppData\Roaming\Python\Python312\site-packages\django\utils\asyncio.py", line 26, in inner
    return func(*args, **kwargs)
           ^^^^^^^^^^^^^^^^^^^^^
  File "C:\Users\Spero\AppData\Roaming\Python\Python312\site-packages\django\db\backends\postgresql\base.py", line 332, in get_new_connection
    connection = self.Database.connect(**conn_params)
                 ^^^^^^^^^^^^^^^^^^^^^^^^^^^^^^^^^^^^
  File "C:\Users\Spero\AppData\Roaming\Python\Python312\site-packages\psycopg2\__init__.py", line 122, in connect
    conn = _connect(dsn, connection_factory=connection_factory, **kwasync)
           ^^^^^^^^^^^^^^^^^^^^^^^^^^^^^^^^^^^^^^^^^^^^^^^^^^^^^^^^^^^^^^^
psycopg2.OperationalError: connection to server at "192.168.1.116", port 5432 failed: No route to host (0x00002751/10065)
	Is the server running on that host and accepting TCP/IP connections?


The above exception was the direct cause of the following exception:

Traceback (most recent call last):
  File "C:\Users\Spero\AppData\Roaming\Python\Python312\site-packages\django\core\handlers\exception.py", line 55, in inner
    response = get_response(request)
               ^^^^^^^^^^^^^^^^^^^^^
  File "C:\Users\Spero\AppData\Roaming\Python\Python312\site-packages\django\core\handlers\base.py", line 197, in _get_response
    response = wrapped_callback(request, *callback_args, **callback_kwargs)
               ^^^^^^^^^^^^^^^^^^^^^^^^^^^^^^^^^^^^^^^^^^^^^^^^^^^^^^^^^^^^
  File "C:\Users\Spero\AppData\Roaming\Python\Python312\site-packages\django\views\decorators\csrf.py", line 65, in _view_wrapper
    return view_func(request, *args, **kwargs)
           ^^^^^^^^^^^^^^^^^^^^^^^^^^^^^^^^^^^
  File "C:\Users\Spero\AppData\Roaming\Python\Python312\site-packages\django\views\generic\base.py", line 104, in view
    return self.dispatch(request, *args, **kwargs)
           ^^^^^^^^^^^^^^^^^^^^^^^^^^^^^^^^^^^^^^^
  File "C:\Users\Spero\AppData\Roaming\Python\Python312\site-packages\rest_framework\views.py", line 515, in dispatch
    response = self.handle_exception(exc)
               ^^^^^^^^^^^^^^^^^^^^^^^^^^
  File "C:\Users\Spero\AppData\Roaming\Python\Python312\site-packages\rest_framework\views.py", line 475, in handle_exception
    self.raise_uncaught_exception(exc)
  File "C:\Users\Spero\AppData\Roaming\Python\Python312\site-packages\rest_framework\views.py", line 486, in raise_uncaught_exception
    raise exc
  File "C:\Users\Spero\AppData\Roaming\Python\Python312\site-packages\rest_framework\views.py", line 512, in dispatch
    response = handler(request, *args, **kwargs)
               ^^^^^^^^^^^^^^^^^^^^^^^^^^^^^^^^^
  File "C:\Spero\Spero-DMS\DMS_goa\admin_web\views.py", line 256, in get
    new_captcha = CaptchaStore.generate_key()
                  ^^^^^^^^^^^^^^^^^^^^^^^^^^^
  File "C:\Users\Spero\AppData\Roaming\Python\Python312\site-packages\captcha\models.py", line 60, in generate_key
    store = cls.objects.create(challenge=challenge, response=response)
            ^^^^^^^^^^^^^^^^^^^^^^^^^^^^^^^^^^^^^^^^^^^^^^^^^^^^^^^^^^
  File "C:\Users\Spero\AppData\Roaming\Python\Python312\site-packages\django\db\models\manager.py", line 87, in manager_method
    return getattr(self.get_queryset(), name)(*args, **kwargs)
           ^^^^^^^^^^^^^^^^^^^^^^^^^^^^^^^^^^^^^^^^^^^^^^^^^^^
  File "C:\Users\Spero\AppData\Roaming\Python\Python312\site-packages\django\db\models\query.py", line 663, in create
    obj.save(force_insert=True, using=self.db)
  File "C:\Users\Spero\AppData\Roaming\Python\Python312\site-packages\captcha\models.py", line 47, in save
    super().save(*args, **kwargs)
  File "C:\Users\Spero\AppData\Roaming\Python\Python312\site-packages\django\db\models\base.py", line 902, in save
    self.save_base(
  File "C:\Users\Spero\AppData\Roaming\Python\Python312\site-packages\django\db\models\base.py", line 1008, in save_base
    updated = self._save_table(
              ^^^^^^^^^^^^^^^^^
  File "C:\Users\Spero\AppData\Roaming\Python\Python312\site-packages\django\db\models\base.py", line 1169, in _save_table
    results = self._do_insert(
              ^^^^^^^^^^^^^^^^
  File "C:\Users\Spero\AppData\Roaming\Python\Python312\site-packages\django\db\models\base.py", line 1210, in _do_insert
    return manager._insert(
           ^^^^^^^^^^^^^^^^
  File "C:\Users\Spero\AppData\Roaming\Python\Python312\site-packages\django\db\models\manager.py", line 87, in manager_method
    return getattr(self.get_queryset(), name)(*args, **kwargs)
           ^^^^^^^^^^^^^^^^^^^^^^^^^^^^^^^^^^^^^^^^^^^^^^^^^^^
  File "C:\Users\Spero\AppData\Roaming\Python\Python312\site-packages\django\db\models\query.py", line 1864, in _insert
    return query.get_compiler(using=using).execute_sql(returning_fields)
           ^^^^^^^^^^^^^^^^^^^^^^^^^^^^^^^^^^^^^^^^^^^^^^^^^^^^^^^^^^^^^
  File "C:\Users\Spero\AppData\Roaming\Python\Python312\site-packages\django\db\models\sql\compiler.py", line 1880, in execute_sql
    with self.connection.cursor() as cursor:
         ^^^^^^^^^^^^^^^^^^^^^^^^
  File "C:\Users\Spero\AppData\Roaming\Python\Python312\site-packages\django\utils\asyncio.py", line 26, in inner
    return func(*args, **kwargs)
           ^^^^^^^^^^^^^^^^^^^^^
  File "C:\Users\Spero\AppData\Roaming\Python\Python312\site-packages\django\db\backends\base\base.py", line 320, in cursor
    return self._cursor()
           ^^^^^^^^^^^^^^
  File "C:\Users\Spero\AppData\Roaming\Python\Python312\site-packages\django\db\backends\base\base.py", line 296, in _cursor
    self.ensure_connection()
  File "C:\Users\Spero\AppData\Roaming\Python\Python312\site-packages\django\utils\asyncio.py", line 26, in inner
    return func(*args, **kwargs)
           ^^^^^^^^^^^^^^^^^^^^^
  File "C:\Users\Spero\AppData\Roaming\Python\Python312\site-packages\django\db\backends\base\base.py", line 278, in ensure_connection
    with self.wrap_database_errors:
         ^^^^^^^^^^^^^^^^^^^^^^^^^
  File "C:\Users\Spero\AppData\Roaming\Python\Python312\site-packages\django\db\utils.py", line 91, in __exit__
    raise dj_exc_value.with_traceback(traceback) from exc_value
  File "C:\Users\Spero\AppData\Roaming\Python\Python312\site-packages\django\db\backends\base\base.py", line 279, in ensure_connection
    self.connect()
  File "C:\Users\Spero\AppData\Roaming\Python\Python312\site-packages\django\utils\asyncio.py", line 26, in inner
    return func(*args, **kwargs)
           ^^^^^^^^^^^^^^^^^^^^^
  File "C:\Users\Spero\AppData\Roaming\Python\Python312\site-packages\django\db\backends\base\base.py", line 256, in connect
    self.connection = self.get_new_connection(conn_params)
                      ^^^^^^^^^^^^^^^^^^^^^^^^^^^^^^^^^^^^
  File "C:\Users\Spero\AppData\Roaming\Python\Python312\site-packages\django\utils\asyncio.py", line 26, in inner
    return func(*args, **kwargs)
           ^^^^^^^^^^^^^^^^^^^^^
  File "C:\Users\Spero\AppData\Roaming\Python\Python312\site-packages\django\db\backends\postgresql\base.py", line 332, in get_new_connection
    connection = self.Database.connect(**conn_params)
                 ^^^^^^^^^^^^^^^^^^^^^^^^^^^^^^^^^^^^
  File "C:\Users\Spero\AppData\Roaming\Python\Python312\site-packages\psycopg2\__init__.py", line 122, in connect
    conn = _connect(dsn, connection_factory=connection_factory, **kwasync)
           ^^^^^^^^^^^^^^^^^^^^^^^^^^^^^^^^^^^^^^^^^^^^^^^^^^^^^^^^^^^^^^^
django.db.utils.OperationalError: connection to server at "192.168.1.116", port 5432 failed: No route to host (0x00002751/10065)
	Is the server running on that host and accepting TCP/IP connections?

ERROR 2025-05-14 16:04:05,366 basehttp "GET /admin_web/login/captcha/ HTTP/1.1" 500 229232
ERROR 2025-05-14 16:04:05,462 log Internal Server Error: /admin_web/login/captcha/
Traceback (most recent call last):
  File "C:\Users\Spero\AppData\Roaming\Python\Python312\site-packages\django\db\backends\base\base.py", line 279, in ensure_connection
    self.connect()
  File "C:\Users\Spero\AppData\Roaming\Python\Python312\site-packages\django\utils\asyncio.py", line 26, in inner
    return func(*args, **kwargs)
           ^^^^^^^^^^^^^^^^^^^^^
  File "C:\Users\Spero\AppData\Roaming\Python\Python312\site-packages\django\db\backends\base\base.py", line 256, in connect
    self.connection = self.get_new_connection(conn_params)
                      ^^^^^^^^^^^^^^^^^^^^^^^^^^^^^^^^^^^^
  File "C:\Users\Spero\AppData\Roaming\Python\Python312\site-packages\django\utils\asyncio.py", line 26, in inner
    return func(*args, **kwargs)
           ^^^^^^^^^^^^^^^^^^^^^
  File "C:\Users\Spero\AppData\Roaming\Python\Python312\site-packages\django\db\backends\postgresql\base.py", line 332, in get_new_connection
    connection = self.Database.connect(**conn_params)
                 ^^^^^^^^^^^^^^^^^^^^^^^^^^^^^^^^^^^^
  File "C:\Users\Spero\AppData\Roaming\Python\Python312\site-packages\psycopg2\__init__.py", line 122, in connect
    conn = _connect(dsn, connection_factory=connection_factory, **kwasync)
           ^^^^^^^^^^^^^^^^^^^^^^^^^^^^^^^^^^^^^^^^^^^^^^^^^^^^^^^^^^^^^^^
psycopg2.OperationalError: connection to server at "192.168.1.116", port 5432 failed: No route to host (0x00002751/10065)
	Is the server running on that host and accepting TCP/IP connections?


The above exception was the direct cause of the following exception:

Traceback (most recent call last):
  File "C:\Users\Spero\AppData\Roaming\Python\Python312\site-packages\django\core\handlers\exception.py", line 55, in inner
    response = get_response(request)
               ^^^^^^^^^^^^^^^^^^^^^
  File "C:\Users\Spero\AppData\Roaming\Python\Python312\site-packages\django\core\handlers\base.py", line 197, in _get_response
    response = wrapped_callback(request, *callback_args, **callback_kwargs)
               ^^^^^^^^^^^^^^^^^^^^^^^^^^^^^^^^^^^^^^^^^^^^^^^^^^^^^^^^^^^^
  File "C:\Users\Spero\AppData\Roaming\Python\Python312\site-packages\django\views\decorators\csrf.py", line 65, in _view_wrapper
    return view_func(request, *args, **kwargs)
           ^^^^^^^^^^^^^^^^^^^^^^^^^^^^^^^^^^^
  File "C:\Users\Spero\AppData\Roaming\Python\Python312\site-packages\django\views\generic\base.py", line 104, in view
    return self.dispatch(request, *args, **kwargs)
           ^^^^^^^^^^^^^^^^^^^^^^^^^^^^^^^^^^^^^^^
  File "C:\Users\Spero\AppData\Roaming\Python\Python312\site-packages\rest_framework\views.py", line 515, in dispatch
    response = self.handle_exception(exc)
               ^^^^^^^^^^^^^^^^^^^^^^^^^^
  File "C:\Users\Spero\AppData\Roaming\Python\Python312\site-packages\rest_framework\views.py", line 475, in handle_exception
    self.raise_uncaught_exception(exc)
  File "C:\Users\Spero\AppData\Roaming\Python\Python312\site-packages\rest_framework\views.py", line 486, in raise_uncaught_exception
    raise exc
  File "C:\Users\Spero\AppData\Roaming\Python\Python312\site-packages\rest_framework\views.py", line 512, in dispatch
    response = handler(request, *args, **kwargs)
               ^^^^^^^^^^^^^^^^^^^^^^^^^^^^^^^^^
  File "C:\Spero\Spero-DMS\DMS_goa\admin_web\views.py", line 256, in get
    new_captcha = CaptchaStore.generate_key()
                  ^^^^^^^^^^^^^^^^^^^^^^^^^^^
  File "C:\Users\Spero\AppData\Roaming\Python\Python312\site-packages\captcha\models.py", line 60, in generate_key
    store = cls.objects.create(challenge=challenge, response=response)
            ^^^^^^^^^^^^^^^^^^^^^^^^^^^^^^^^^^^^^^^^^^^^^^^^^^^^^^^^^^
  File "C:\Users\Spero\AppData\Roaming\Python\Python312\site-packages\django\db\models\manager.py", line 87, in manager_method
    return getattr(self.get_queryset(), name)(*args, **kwargs)
           ^^^^^^^^^^^^^^^^^^^^^^^^^^^^^^^^^^^^^^^^^^^^^^^^^^^
  File "C:\Users\Spero\AppData\Roaming\Python\Python312\site-packages\django\db\models\query.py", line 663, in create
    obj.save(force_insert=True, using=self.db)
  File "C:\Users\Spero\AppData\Roaming\Python\Python312\site-packages\captcha\models.py", line 47, in save
    super().save(*args, **kwargs)
  File "C:\Users\Spero\AppData\Roaming\Python\Python312\site-packages\django\db\models\base.py", line 902, in save
    self.save_base(
  File "C:\Users\Spero\AppData\Roaming\Python\Python312\site-packages\django\db\models\base.py", line 1008, in save_base
    updated = self._save_table(
              ^^^^^^^^^^^^^^^^^
  File "C:\Users\Spero\AppData\Roaming\Python\Python312\site-packages\django\db\models\base.py", line 1169, in _save_table
    results = self._do_insert(
              ^^^^^^^^^^^^^^^^
  File "C:\Users\Spero\AppData\Roaming\Python\Python312\site-packages\django\db\models\base.py", line 1210, in _do_insert
    return manager._insert(
           ^^^^^^^^^^^^^^^^
  File "C:\Users\Spero\AppData\Roaming\Python\Python312\site-packages\django\db\models\manager.py", line 87, in manager_method
    return getattr(self.get_queryset(), name)(*args, **kwargs)
           ^^^^^^^^^^^^^^^^^^^^^^^^^^^^^^^^^^^^^^^^^^^^^^^^^^^
  File "C:\Users\Spero\AppData\Roaming\Python\Python312\site-packages\django\db\models\query.py", line 1864, in _insert
    return query.get_compiler(using=using).execute_sql(returning_fields)
           ^^^^^^^^^^^^^^^^^^^^^^^^^^^^^^^^^^^^^^^^^^^^^^^^^^^^^^^^^^^^^
  File "C:\Users\Spero\AppData\Roaming\Python\Python312\site-packages\django\db\models\sql\compiler.py", line 1880, in execute_sql
    with self.connection.cursor() as cursor:
         ^^^^^^^^^^^^^^^^^^^^^^^^
  File "C:\Users\Spero\AppData\Roaming\Python\Python312\site-packages\django\utils\asyncio.py", line 26, in inner
    return func(*args, **kwargs)
           ^^^^^^^^^^^^^^^^^^^^^
  File "C:\Users\Spero\AppData\Roaming\Python\Python312\site-packages\django\db\backends\base\base.py", line 320, in cursor
    return self._cursor()
           ^^^^^^^^^^^^^^
  File "C:\Users\Spero\AppData\Roaming\Python\Python312\site-packages\django\db\backends\base\base.py", line 296, in _cursor
    self.ensure_connection()
  File "C:\Users\Spero\AppData\Roaming\Python\Python312\site-packages\django\utils\asyncio.py", line 26, in inner
    return func(*args, **kwargs)
           ^^^^^^^^^^^^^^^^^^^^^
  File "C:\Users\Spero\AppData\Roaming\Python\Python312\site-packages\django\db\backends\base\base.py", line 278, in ensure_connection
    with self.wrap_database_errors:
         ^^^^^^^^^^^^^^^^^^^^^^^^^
  File "C:\Users\Spero\AppData\Roaming\Python\Python312\site-packages\django\db\utils.py", line 91, in __exit__
    raise dj_exc_value.with_traceback(traceback) from exc_value
  File "C:\Users\Spero\AppData\Roaming\Python\Python312\site-packages\django\db\backends\base\base.py", line 279, in ensure_connection
    self.connect()
  File "C:\Users\Spero\AppData\Roaming\Python\Python312\site-packages\django\utils\asyncio.py", line 26, in inner
    return func(*args, **kwargs)
           ^^^^^^^^^^^^^^^^^^^^^
  File "C:\Users\Spero\AppData\Roaming\Python\Python312\site-packages\django\db\backends\base\base.py", line 256, in connect
    self.connection = self.get_new_connection(conn_params)
                      ^^^^^^^^^^^^^^^^^^^^^^^^^^^^^^^^^^^^
  File "C:\Users\Spero\AppData\Roaming\Python\Python312\site-packages\django\utils\asyncio.py", line 26, in inner
    return func(*args, **kwargs)
           ^^^^^^^^^^^^^^^^^^^^^
  File "C:\Users\Spero\AppData\Roaming\Python\Python312\site-packages\django\db\backends\postgresql\base.py", line 332, in get_new_connection
    connection = self.Database.connect(**conn_params)
                 ^^^^^^^^^^^^^^^^^^^^^^^^^^^^^^^^^^^^
  File "C:\Users\Spero\AppData\Roaming\Python\Python312\site-packages\psycopg2\__init__.py", line 122, in connect
    conn = _connect(dsn, connection_factory=connection_factory, **kwasync)
           ^^^^^^^^^^^^^^^^^^^^^^^^^^^^^^^^^^^^^^^^^^^^^^^^^^^^^^^^^^^^^^^
django.db.utils.OperationalError: connection to server at "192.168.1.116", port 5432 failed: No route to host (0x00002751/10065)
	Is the server running on that host and accepting TCP/IP connections?

ERROR 2025-05-14 16:04:05,466 basehttp "GET /admin_web/login/captcha/ HTTP/1.1" 500 229232
ERROR 2025-05-14 16:04:09,447 log Internal Server Error: /admin_web/login/captcha/
Traceback (most recent call last):
  File "C:\Users\Spero\AppData\Roaming\Python\Python312\site-packages\django\db\backends\base\base.py", line 279, in ensure_connection
    self.connect()
  File "C:\Users\Spero\AppData\Roaming\Python\Python312\site-packages\django\utils\asyncio.py", line 26, in inner
    return func(*args, **kwargs)
           ^^^^^^^^^^^^^^^^^^^^^
  File "C:\Users\Spero\AppData\Roaming\Python\Python312\site-packages\django\db\backends\base\base.py", line 256, in connect
    self.connection = self.get_new_connection(conn_params)
                      ^^^^^^^^^^^^^^^^^^^^^^^^^^^^^^^^^^^^
  File "C:\Users\Spero\AppData\Roaming\Python\Python312\site-packages\django\utils\asyncio.py", line 26, in inner
    return func(*args, **kwargs)
           ^^^^^^^^^^^^^^^^^^^^^
  File "C:\Users\Spero\AppData\Roaming\Python\Python312\site-packages\django\db\backends\postgresql\base.py", line 332, in get_new_connection
    connection = self.Database.connect(**conn_params)
                 ^^^^^^^^^^^^^^^^^^^^^^^^^^^^^^^^^^^^
  File "C:\Users\Spero\AppData\Roaming\Python\Python312\site-packages\psycopg2\__init__.py", line 122, in connect
    conn = _connect(dsn, connection_factory=connection_factory, **kwasync)
           ^^^^^^^^^^^^^^^^^^^^^^^^^^^^^^^^^^^^^^^^^^^^^^^^^^^^^^^^^^^^^^^
psycopg2.OperationalError: connection to server at "192.168.1.116", port 5432 failed: No route to host (0x00002751/10065)
	Is the server running on that host and accepting TCP/IP connections?


The above exception was the direct cause of the following exception:

Traceback (most recent call last):
  File "C:\Users\Spero\AppData\Roaming\Python\Python312\site-packages\django\core\handlers\exception.py", line 55, in inner
    response = get_response(request)
               ^^^^^^^^^^^^^^^^^^^^^
  File "C:\Users\Spero\AppData\Roaming\Python\Python312\site-packages\django\core\handlers\base.py", line 197, in _get_response
    response = wrapped_callback(request, *callback_args, **callback_kwargs)
               ^^^^^^^^^^^^^^^^^^^^^^^^^^^^^^^^^^^^^^^^^^^^^^^^^^^^^^^^^^^^
  File "C:\Users\Spero\AppData\Roaming\Python\Python312\site-packages\django\views\decorators\csrf.py", line 65, in _view_wrapper
    return view_func(request, *args, **kwargs)
           ^^^^^^^^^^^^^^^^^^^^^^^^^^^^^^^^^^^
  File "C:\Users\Spero\AppData\Roaming\Python\Python312\site-packages\django\views\generic\base.py", line 104, in view
    return self.dispatch(request, *args, **kwargs)
           ^^^^^^^^^^^^^^^^^^^^^^^^^^^^^^^^^^^^^^^
  File "C:\Users\Spero\AppData\Roaming\Python\Python312\site-packages\rest_framework\views.py", line 515, in dispatch
    response = self.handle_exception(exc)
               ^^^^^^^^^^^^^^^^^^^^^^^^^^
  File "C:\Users\Spero\AppData\Roaming\Python\Python312\site-packages\rest_framework\views.py", line 475, in handle_exception
    self.raise_uncaught_exception(exc)
  File "C:\Users\Spero\AppData\Roaming\Python\Python312\site-packages\rest_framework\views.py", line 486, in raise_uncaught_exception
    raise exc
  File "C:\Users\Spero\AppData\Roaming\Python\Python312\site-packages\rest_framework\views.py", line 512, in dispatch
    response = handler(request, *args, **kwargs)
               ^^^^^^^^^^^^^^^^^^^^^^^^^^^^^^^^^
  File "C:\Spero\Spero-DMS\DMS_goa\admin_web\views.py", line 256, in get
    new_captcha = CaptchaStore.generate_key()
                  ^^^^^^^^^^^^^^^^^^^^^^^^^^^
  File "C:\Users\Spero\AppData\Roaming\Python\Python312\site-packages\captcha\models.py", line 60, in generate_key
    store = cls.objects.create(challenge=challenge, response=response)
            ^^^^^^^^^^^^^^^^^^^^^^^^^^^^^^^^^^^^^^^^^^^^^^^^^^^^^^^^^^
  File "C:\Users\Spero\AppData\Roaming\Python\Python312\site-packages\django\db\models\manager.py", line 87, in manager_method
    return getattr(self.get_queryset(), name)(*args, **kwargs)
           ^^^^^^^^^^^^^^^^^^^^^^^^^^^^^^^^^^^^^^^^^^^^^^^^^^^
  File "C:\Users\Spero\AppData\Roaming\Python\Python312\site-packages\django\db\models\query.py", line 663, in create
    obj.save(force_insert=True, using=self.db)
  File "C:\Users\Spero\AppData\Roaming\Python\Python312\site-packages\captcha\models.py", line 47, in save
    super().save(*args, **kwargs)
  File "C:\Users\Spero\AppData\Roaming\Python\Python312\site-packages\django\db\models\base.py", line 902, in save
    self.save_base(
  File "C:\Users\Spero\AppData\Roaming\Python\Python312\site-packages\django\db\models\base.py", line 1008, in save_base
    updated = self._save_table(
              ^^^^^^^^^^^^^^^^^
  File "C:\Users\Spero\AppData\Roaming\Python\Python312\site-packages\django\db\models\base.py", line 1169, in _save_table
    results = self._do_insert(
              ^^^^^^^^^^^^^^^^
  File "C:\Users\Spero\AppData\Roaming\Python\Python312\site-packages\django\db\models\base.py", line 1210, in _do_insert
    return manager._insert(
           ^^^^^^^^^^^^^^^^
  File "C:\Users\Spero\AppData\Roaming\Python\Python312\site-packages\django\db\models\manager.py", line 87, in manager_method
    return getattr(self.get_queryset(), name)(*args, **kwargs)
           ^^^^^^^^^^^^^^^^^^^^^^^^^^^^^^^^^^^^^^^^^^^^^^^^^^^
  File "C:\Users\Spero\AppData\Roaming\Python\Python312\site-packages\django\db\models\query.py", line 1864, in _insert
    return query.get_compiler(using=using).execute_sql(returning_fields)
           ^^^^^^^^^^^^^^^^^^^^^^^^^^^^^^^^^^^^^^^^^^^^^^^^^^^^^^^^^^^^^
  File "C:\Users\Spero\AppData\Roaming\Python\Python312\site-packages\django\db\models\sql\compiler.py", line 1880, in execute_sql
    with self.connection.cursor() as cursor:
         ^^^^^^^^^^^^^^^^^^^^^^^^
  File "C:\Users\Spero\AppData\Roaming\Python\Python312\site-packages\django\utils\asyncio.py", line 26, in inner
    return func(*args, **kwargs)
           ^^^^^^^^^^^^^^^^^^^^^
  File "C:\Users\Spero\AppData\Roaming\Python\Python312\site-packages\django\db\backends\base\base.py", line 320, in cursor
    return self._cursor()
           ^^^^^^^^^^^^^^
  File "C:\Users\Spero\AppData\Roaming\Python\Python312\site-packages\django\db\backends\base\base.py", line 296, in _cursor
    self.ensure_connection()
  File "C:\Users\Spero\AppData\Roaming\Python\Python312\site-packages\django\utils\asyncio.py", line 26, in inner
    return func(*args, **kwargs)
           ^^^^^^^^^^^^^^^^^^^^^
  File "C:\Users\Spero\AppData\Roaming\Python\Python312\site-packages\django\db\backends\base\base.py", line 278, in ensure_connection
    with self.wrap_database_errors:
         ^^^^^^^^^^^^^^^^^^^^^^^^^
  File "C:\Users\Spero\AppData\Roaming\Python\Python312\site-packages\django\db\utils.py", line 91, in __exit__
    raise dj_exc_value.with_traceback(traceback) from exc_value
  File "C:\Users\Spero\AppData\Roaming\Python\Python312\site-packages\django\db\backends\base\base.py", line 279, in ensure_connection
    self.connect()
  File "C:\Users\Spero\AppData\Roaming\Python\Python312\site-packages\django\utils\asyncio.py", line 26, in inner
    return func(*args, **kwargs)
           ^^^^^^^^^^^^^^^^^^^^^
  File "C:\Users\Spero\AppData\Roaming\Python\Python312\site-packages\django\db\backends\base\base.py", line 256, in connect
    self.connection = self.get_new_connection(conn_params)
                      ^^^^^^^^^^^^^^^^^^^^^^^^^^^^^^^^^^^^
  File "C:\Users\Spero\AppData\Roaming\Python\Python312\site-packages\django\utils\asyncio.py", line 26, in inner
    return func(*args, **kwargs)
           ^^^^^^^^^^^^^^^^^^^^^
  File "C:\Users\Spero\AppData\Roaming\Python\Python312\site-packages\django\db\backends\postgresql\base.py", line 332, in get_new_connection
    connection = self.Database.connect(**conn_params)
                 ^^^^^^^^^^^^^^^^^^^^^^^^^^^^^^^^^^^^
  File "C:\Users\Spero\AppData\Roaming\Python\Python312\site-packages\psycopg2\__init__.py", line 122, in connect
    conn = _connect(dsn, connection_factory=connection_factory, **kwasync)
           ^^^^^^^^^^^^^^^^^^^^^^^^^^^^^^^^^^^^^^^^^^^^^^^^^^^^^^^^^^^^^^^
django.db.utils.OperationalError: connection to server at "192.168.1.116", port 5432 failed: No route to host (0x00002751/10065)
	Is the server running on that host and accepting TCP/IP connections?

ERROR 2025-05-14 16:04:09,454 basehttp "GET /admin_web/login/captcha/ HTTP/1.1" 500 229232
ERROR 2025-05-14 16:04:09,575 log Internal Server Error: /admin_web/login/captcha/
Traceback (most recent call last):
  File "C:\Users\Spero\AppData\Roaming\Python\Python312\site-packages\django\db\backends\base\base.py", line 279, in ensure_connection
    self.connect()
  File "C:\Users\Spero\AppData\Roaming\Python\Python312\site-packages\django\utils\asyncio.py", line 26, in inner
    return func(*args, **kwargs)
           ^^^^^^^^^^^^^^^^^^^^^
  File "C:\Users\Spero\AppData\Roaming\Python\Python312\site-packages\django\db\backends\base\base.py", line 256, in connect
    self.connection = self.get_new_connection(conn_params)
                      ^^^^^^^^^^^^^^^^^^^^^^^^^^^^^^^^^^^^
  File "C:\Users\Spero\AppData\Roaming\Python\Python312\site-packages\django\utils\asyncio.py", line 26, in inner
    return func(*args, **kwargs)
           ^^^^^^^^^^^^^^^^^^^^^
  File "C:\Users\Spero\AppData\Roaming\Python\Python312\site-packages\django\db\backends\postgresql\base.py", line 332, in get_new_connection
    connection = self.Database.connect(**conn_params)
                 ^^^^^^^^^^^^^^^^^^^^^^^^^^^^^^^^^^^^
  File "C:\Users\Spero\AppData\Roaming\Python\Python312\site-packages\psycopg2\__init__.py", line 122, in connect
    conn = _connect(dsn, connection_factory=connection_factory, **kwasync)
           ^^^^^^^^^^^^^^^^^^^^^^^^^^^^^^^^^^^^^^^^^^^^^^^^^^^^^^^^^^^^^^^
psycopg2.OperationalError: connection to server at "192.168.1.116", port 5432 failed: No route to host (0x00002751/10065)
	Is the server running on that host and accepting TCP/IP connections?


The above exception was the direct cause of the following exception:

Traceback (most recent call last):
  File "C:\Users\Spero\AppData\Roaming\Python\Python312\site-packages\django\core\handlers\exception.py", line 55, in inner
    response = get_response(request)
               ^^^^^^^^^^^^^^^^^^^^^
  File "C:\Users\Spero\AppData\Roaming\Python\Python312\site-packages\django\core\handlers\base.py", line 197, in _get_response
    response = wrapped_callback(request, *callback_args, **callback_kwargs)
               ^^^^^^^^^^^^^^^^^^^^^^^^^^^^^^^^^^^^^^^^^^^^^^^^^^^^^^^^^^^^
  File "C:\Users\Spero\AppData\Roaming\Python\Python312\site-packages\django\views\decorators\csrf.py", line 65, in _view_wrapper
    return view_func(request, *args, **kwargs)
           ^^^^^^^^^^^^^^^^^^^^^^^^^^^^^^^^^^^
  File "C:\Users\Spero\AppData\Roaming\Python\Python312\site-packages\django\views\generic\base.py", line 104, in view
    return self.dispatch(request, *args, **kwargs)
           ^^^^^^^^^^^^^^^^^^^^^^^^^^^^^^^^^^^^^^^
  File "C:\Users\Spero\AppData\Roaming\Python\Python312\site-packages\rest_framework\views.py", line 515, in dispatch
    response = self.handle_exception(exc)
               ^^^^^^^^^^^^^^^^^^^^^^^^^^
  File "C:\Users\Spero\AppData\Roaming\Python\Python312\site-packages\rest_framework\views.py", line 475, in handle_exception
    self.raise_uncaught_exception(exc)
  File "C:\Users\Spero\AppData\Roaming\Python\Python312\site-packages\rest_framework\views.py", line 486, in raise_uncaught_exception
    raise exc
  File "C:\Users\Spero\AppData\Roaming\Python\Python312\site-packages\rest_framework\views.py", line 512, in dispatch
    response = handler(request, *args, **kwargs)
               ^^^^^^^^^^^^^^^^^^^^^^^^^^^^^^^^^
  File "C:\Spero\Spero-DMS\DMS_goa\admin_web\views.py", line 256, in get
    new_captcha = CaptchaStore.generate_key()
                  ^^^^^^^^^^^^^^^^^^^^^^^^^^^
  File "C:\Users\Spero\AppData\Roaming\Python\Python312\site-packages\captcha\models.py", line 60, in generate_key
    store = cls.objects.create(challenge=challenge, response=response)
            ^^^^^^^^^^^^^^^^^^^^^^^^^^^^^^^^^^^^^^^^^^^^^^^^^^^^^^^^^^
  File "C:\Users\Spero\AppData\Roaming\Python\Python312\site-packages\django\db\models\manager.py", line 87, in manager_method
    return getattr(self.get_queryset(), name)(*args, **kwargs)
           ^^^^^^^^^^^^^^^^^^^^^^^^^^^^^^^^^^^^^^^^^^^^^^^^^^^
  File "C:\Users\Spero\AppData\Roaming\Python\Python312\site-packages\django\db\models\query.py", line 663, in create
    obj.save(force_insert=True, using=self.db)
  File "C:\Users\Spero\AppData\Roaming\Python\Python312\site-packages\captcha\models.py", line 47, in save
    super().save(*args, **kwargs)
  File "C:\Users\Spero\AppData\Roaming\Python\Python312\site-packages\django\db\models\base.py", line 902, in save
    self.save_base(
  File "C:\Users\Spero\AppData\Roaming\Python\Python312\site-packages\django\db\models\base.py", line 1008, in save_base
    updated = self._save_table(
              ^^^^^^^^^^^^^^^^^
  File "C:\Users\Spero\AppData\Roaming\Python\Python312\site-packages\django\db\models\base.py", line 1169, in _save_table
    results = self._do_insert(
              ^^^^^^^^^^^^^^^^
  File "C:\Users\Spero\AppData\Roaming\Python\Python312\site-packages\django\db\models\base.py", line 1210, in _do_insert
    return manager._insert(
           ^^^^^^^^^^^^^^^^
  File "C:\Users\Spero\AppData\Roaming\Python\Python312\site-packages\django\db\models\manager.py", line 87, in manager_method
    return getattr(self.get_queryset(), name)(*args, **kwargs)
           ^^^^^^^^^^^^^^^^^^^^^^^^^^^^^^^^^^^^^^^^^^^^^^^^^^^
  File "C:\Users\Spero\AppData\Roaming\Python\Python312\site-packages\django\db\models\query.py", line 1864, in _insert
    return query.get_compiler(using=using).execute_sql(returning_fields)
           ^^^^^^^^^^^^^^^^^^^^^^^^^^^^^^^^^^^^^^^^^^^^^^^^^^^^^^^^^^^^^
  File "C:\Users\Spero\AppData\Roaming\Python\Python312\site-packages\django\db\models\sql\compiler.py", line 1880, in execute_sql
    with self.connection.cursor() as cursor:
         ^^^^^^^^^^^^^^^^^^^^^^^^
  File "C:\Users\Spero\AppData\Roaming\Python\Python312\site-packages\django\utils\asyncio.py", line 26, in inner
    return func(*args, **kwargs)
           ^^^^^^^^^^^^^^^^^^^^^
  File "C:\Users\Spero\AppData\Roaming\Python\Python312\site-packages\django\db\backends\base\base.py", line 320, in cursor
    return self._cursor()
           ^^^^^^^^^^^^^^
  File "C:\Users\Spero\AppData\Roaming\Python\Python312\site-packages\django\db\backends\base\base.py", line 296, in _cursor
    self.ensure_connection()
  File "C:\Users\Spero\AppData\Roaming\Python\Python312\site-packages\django\utils\asyncio.py", line 26, in inner
    return func(*args, **kwargs)
           ^^^^^^^^^^^^^^^^^^^^^
  File "C:\Users\Spero\AppData\Roaming\Python\Python312\site-packages\django\db\backends\base\base.py", line 278, in ensure_connection
    with self.wrap_database_errors:
         ^^^^^^^^^^^^^^^^^^^^^^^^^
  File "C:\Users\Spero\AppData\Roaming\Python\Python312\site-packages\django\db\utils.py", line 91, in __exit__
    raise dj_exc_value.with_traceback(traceback) from exc_value
  File "C:\Users\Spero\AppData\Roaming\Python\Python312\site-packages\django\db\backends\base\base.py", line 279, in ensure_connection
    self.connect()
  File "C:\Users\Spero\AppData\Roaming\Python\Python312\site-packages\django\utils\asyncio.py", line 26, in inner
    return func(*args, **kwargs)
           ^^^^^^^^^^^^^^^^^^^^^
  File "C:\Users\Spero\AppData\Roaming\Python\Python312\site-packages\django\db\backends\base\base.py", line 256, in connect
    self.connection = self.get_new_connection(conn_params)
                      ^^^^^^^^^^^^^^^^^^^^^^^^^^^^^^^^^^^^
  File "C:\Users\Spero\AppData\Roaming\Python\Python312\site-packages\django\utils\asyncio.py", line 26, in inner
    return func(*args, **kwargs)
           ^^^^^^^^^^^^^^^^^^^^^
  File "C:\Users\Spero\AppData\Roaming\Python\Python312\site-packages\django\db\backends\postgresql\base.py", line 332, in get_new_connection
    connection = self.Database.connect(**conn_params)
                 ^^^^^^^^^^^^^^^^^^^^^^^^^^^^^^^^^^^^
  File "C:\Users\Spero\AppData\Roaming\Python\Python312\site-packages\psycopg2\__init__.py", line 122, in connect
    conn = _connect(dsn, connection_factory=connection_factory, **kwasync)
           ^^^^^^^^^^^^^^^^^^^^^^^^^^^^^^^^^^^^^^^^^^^^^^^^^^^^^^^^^^^^^^^
django.db.utils.OperationalError: connection to server at "192.168.1.116", port 5432 failed: No route to host (0x00002751/10065)
	Is the server running on that host and accepting TCP/IP connections?

ERROR 2025-05-14 16:04:09,582 basehttp "GET /admin_web/login/captcha/ HTTP/1.1" 500 229232
ERROR 2025-05-14 16:04:12,094 log Internal Server Error: /admin_web/login/captcha/
Traceback (most recent call last):
  File "C:\Users\Spero\AppData\Roaming\Python\Python312\site-packages\django\db\backends\base\base.py", line 279, in ensure_connection
    self.connect()
  File "C:\Users\Spero\AppData\Roaming\Python\Python312\site-packages\django\utils\asyncio.py", line 26, in inner
    return func(*args, **kwargs)
           ^^^^^^^^^^^^^^^^^^^^^
  File "C:\Users\Spero\AppData\Roaming\Python\Python312\site-packages\django\db\backends\base\base.py", line 256, in connect
    self.connection = self.get_new_connection(conn_params)
                      ^^^^^^^^^^^^^^^^^^^^^^^^^^^^^^^^^^^^
  File "C:\Users\Spero\AppData\Roaming\Python\Python312\site-packages\django\utils\asyncio.py", line 26, in inner
    return func(*args, **kwargs)
           ^^^^^^^^^^^^^^^^^^^^^
  File "C:\Users\Spero\AppData\Roaming\Python\Python312\site-packages\django\db\backends\postgresql\base.py", line 332, in get_new_connection
    connection = self.Database.connect(**conn_params)
                 ^^^^^^^^^^^^^^^^^^^^^^^^^^^^^^^^^^^^
  File "C:\Users\Spero\AppData\Roaming\Python\Python312\site-packages\psycopg2\__init__.py", line 122, in connect
    conn = _connect(dsn, connection_factory=connection_factory, **kwasync)
           ^^^^^^^^^^^^^^^^^^^^^^^^^^^^^^^^^^^^^^^^^^^^^^^^^^^^^^^^^^^^^^^
psycopg2.OperationalError: connection to server at "192.168.1.116", port 5432 failed: No route to host (0x00002751/10065)
	Is the server running on that host and accepting TCP/IP connections?


The above exception was the direct cause of the following exception:

Traceback (most recent call last):
  File "C:\Users\Spero\AppData\Roaming\Python\Python312\site-packages\django\core\handlers\exception.py", line 55, in inner
    response = get_response(request)
               ^^^^^^^^^^^^^^^^^^^^^
  File "C:\Users\Spero\AppData\Roaming\Python\Python312\site-packages\django\core\handlers\base.py", line 197, in _get_response
    response = wrapped_callback(request, *callback_args, **callback_kwargs)
               ^^^^^^^^^^^^^^^^^^^^^^^^^^^^^^^^^^^^^^^^^^^^^^^^^^^^^^^^^^^^
  File "C:\Users\Spero\AppData\Roaming\Python\Python312\site-packages\django\views\decorators\csrf.py", line 65, in _view_wrapper
    return view_func(request, *args, **kwargs)
           ^^^^^^^^^^^^^^^^^^^^^^^^^^^^^^^^^^^
  File "C:\Users\Spero\AppData\Roaming\Python\Python312\site-packages\django\views\generic\base.py", line 104, in view
    return self.dispatch(request, *args, **kwargs)
           ^^^^^^^^^^^^^^^^^^^^^^^^^^^^^^^^^^^^^^^
  File "C:\Users\Spero\AppData\Roaming\Python\Python312\site-packages\rest_framework\views.py", line 515, in dispatch
    response = self.handle_exception(exc)
               ^^^^^^^^^^^^^^^^^^^^^^^^^^
  File "C:\Users\Spero\AppData\Roaming\Python\Python312\site-packages\rest_framework\views.py", line 475, in handle_exception
    self.raise_uncaught_exception(exc)
  File "C:\Users\Spero\AppData\Roaming\Python\Python312\site-packages\rest_framework\views.py", line 486, in raise_uncaught_exception
    raise exc
  File "C:\Users\Spero\AppData\Roaming\Python\Python312\site-packages\rest_framework\views.py", line 512, in dispatch
    response = handler(request, *args, **kwargs)
               ^^^^^^^^^^^^^^^^^^^^^^^^^^^^^^^^^
  File "C:\Spero\Spero-DMS\DMS_goa\admin_web\views.py", line 256, in get
    new_captcha = CaptchaStore.generate_key()
                  ^^^^^^^^^^^^^^^^^^^^^^^^^^^
  File "C:\Users\Spero\AppData\Roaming\Python\Python312\site-packages\captcha\models.py", line 60, in generate_key
    store = cls.objects.create(challenge=challenge, response=response)
            ^^^^^^^^^^^^^^^^^^^^^^^^^^^^^^^^^^^^^^^^^^^^^^^^^^^^^^^^^^
  File "C:\Users\Spero\AppData\Roaming\Python\Python312\site-packages\django\db\models\manager.py", line 87, in manager_method
    return getattr(self.get_queryset(), name)(*args, **kwargs)
           ^^^^^^^^^^^^^^^^^^^^^^^^^^^^^^^^^^^^^^^^^^^^^^^^^^^
  File "C:\Users\Spero\AppData\Roaming\Python\Python312\site-packages\django\db\models\query.py", line 663, in create
    obj.save(force_insert=True, using=self.db)
  File "C:\Users\Spero\AppData\Roaming\Python\Python312\site-packages\captcha\models.py", line 47, in save
    super().save(*args, **kwargs)
  File "C:\Users\Spero\AppData\Roaming\Python\Python312\site-packages\django\db\models\base.py", line 902, in save
    self.save_base(
  File "C:\Users\Spero\AppData\Roaming\Python\Python312\site-packages\django\db\models\base.py", line 1008, in save_base
    updated = self._save_table(
              ^^^^^^^^^^^^^^^^^
  File "C:\Users\Spero\AppData\Roaming\Python\Python312\site-packages\django\db\models\base.py", line 1169, in _save_table
    results = self._do_insert(
              ^^^^^^^^^^^^^^^^
  File "C:\Users\Spero\AppData\Roaming\Python\Python312\site-packages\django\db\models\base.py", line 1210, in _do_insert
    return manager._insert(
           ^^^^^^^^^^^^^^^^
  File "C:\Users\Spero\AppData\Roaming\Python\Python312\site-packages\django\db\models\manager.py", line 87, in manager_method
    return getattr(self.get_queryset(), name)(*args, **kwargs)
           ^^^^^^^^^^^^^^^^^^^^^^^^^^^^^^^^^^^^^^^^^^^^^^^^^^^
  File "C:\Users\Spero\AppData\Roaming\Python\Python312\site-packages\django\db\models\query.py", line 1864, in _insert
    return query.get_compiler(using=using).execute_sql(returning_fields)
           ^^^^^^^^^^^^^^^^^^^^^^^^^^^^^^^^^^^^^^^^^^^^^^^^^^^^^^^^^^^^^
  File "C:\Users\Spero\AppData\Roaming\Python\Python312\site-packages\django\db\models\sql\compiler.py", line 1880, in execute_sql
    with self.connection.cursor() as cursor:
         ^^^^^^^^^^^^^^^^^^^^^^^^
  File "C:\Users\Spero\AppData\Roaming\Python\Python312\site-packages\django\utils\asyncio.py", line 26, in inner
    return func(*args, **kwargs)
           ^^^^^^^^^^^^^^^^^^^^^
  File "C:\Users\Spero\AppData\Roaming\Python\Python312\site-packages\django\db\backends\base\base.py", line 320, in cursor
    return self._cursor()
           ^^^^^^^^^^^^^^
  File "C:\Users\Spero\AppData\Roaming\Python\Python312\site-packages\django\db\backends\base\base.py", line 296, in _cursor
    self.ensure_connection()
  File "C:\Users\Spero\AppData\Roaming\Python\Python312\site-packages\django\utils\asyncio.py", line 26, in inner
    return func(*args, **kwargs)
           ^^^^^^^^^^^^^^^^^^^^^
  File "C:\Users\Spero\AppData\Roaming\Python\Python312\site-packages\django\db\backends\base\base.py", line 278, in ensure_connection
    with self.wrap_database_errors:
         ^^^^^^^^^^^^^^^^^^^^^^^^^
  File "C:\Users\Spero\AppData\Roaming\Python\Python312\site-packages\django\db\utils.py", line 91, in __exit__
    raise dj_exc_value.with_traceback(traceback) from exc_value
  File "C:\Users\Spero\AppData\Roaming\Python\Python312\site-packages\django\db\backends\base\base.py", line 279, in ensure_connection
    self.connect()
  File "C:\Users\Spero\AppData\Roaming\Python\Python312\site-packages\django\utils\asyncio.py", line 26, in inner
    return func(*args, **kwargs)
           ^^^^^^^^^^^^^^^^^^^^^
  File "C:\Users\Spero\AppData\Roaming\Python\Python312\site-packages\django\db\backends\base\base.py", line 256, in connect
    self.connection = self.get_new_connection(conn_params)
                      ^^^^^^^^^^^^^^^^^^^^^^^^^^^^^^^^^^^^
  File "C:\Users\Spero\AppData\Roaming\Python\Python312\site-packages\django\utils\asyncio.py", line 26, in inner
    return func(*args, **kwargs)
           ^^^^^^^^^^^^^^^^^^^^^
  File "C:\Users\Spero\AppData\Roaming\Python\Python312\site-packages\django\db\backends\postgresql\base.py", line 332, in get_new_connection
    connection = self.Database.connect(**conn_params)
                 ^^^^^^^^^^^^^^^^^^^^^^^^^^^^^^^^^^^^
  File "C:\Users\Spero\AppData\Roaming\Python\Python312\site-packages\psycopg2\__init__.py", line 122, in connect
    conn = _connect(dsn, connection_factory=connection_factory, **kwasync)
           ^^^^^^^^^^^^^^^^^^^^^^^^^^^^^^^^^^^^^^^^^^^^^^^^^^^^^^^^^^^^^^^
django.db.utils.OperationalError: connection to server at "192.168.1.116", port 5432 failed: No route to host (0x00002751/10065)
	Is the server running on that host and accepting TCP/IP connections?

ERROR 2025-05-14 16:04:12,099 basehttp "GET /admin_web/login/captcha/ HTTP/1.1" 500 229232
ERROR 2025-05-14 16:04:12,211 log Internal Server Error: /admin_web/login/captcha/
Traceback (most recent call last):
  File "C:\Users\Spero\AppData\Roaming\Python\Python312\site-packages\django\db\backends\base\base.py", line 279, in ensure_connection
    self.connect()
  File "C:\Users\Spero\AppData\Roaming\Python\Python312\site-packages\django\utils\asyncio.py", line 26, in inner
    return func(*args, **kwargs)
           ^^^^^^^^^^^^^^^^^^^^^
  File "C:\Users\Spero\AppData\Roaming\Python\Python312\site-packages\django\db\backends\base\base.py", line 256, in connect
    self.connection = self.get_new_connection(conn_params)
                      ^^^^^^^^^^^^^^^^^^^^^^^^^^^^^^^^^^^^
  File "C:\Users\Spero\AppData\Roaming\Python\Python312\site-packages\django\utils\asyncio.py", line 26, in inner
    return func(*args, **kwargs)
           ^^^^^^^^^^^^^^^^^^^^^
  File "C:\Users\Spero\AppData\Roaming\Python\Python312\site-packages\django\db\backends\postgresql\base.py", line 332, in get_new_connection
    connection = self.Database.connect(**conn_params)
                 ^^^^^^^^^^^^^^^^^^^^^^^^^^^^^^^^^^^^
  File "C:\Users\Spero\AppData\Roaming\Python\Python312\site-packages\psycopg2\__init__.py", line 122, in connect
    conn = _connect(dsn, connection_factory=connection_factory, **kwasync)
           ^^^^^^^^^^^^^^^^^^^^^^^^^^^^^^^^^^^^^^^^^^^^^^^^^^^^^^^^^^^^^^^
psycopg2.OperationalError: connection to server at "192.168.1.116", port 5432 failed: No route to host (0x00002751/10065)
	Is the server running on that host and accepting TCP/IP connections?


The above exception was the direct cause of the following exception:

Traceback (most recent call last):
  File "C:\Users\Spero\AppData\Roaming\Python\Python312\site-packages\django\core\handlers\exception.py", line 55, in inner
    response = get_response(request)
               ^^^^^^^^^^^^^^^^^^^^^
  File "C:\Users\Spero\AppData\Roaming\Python\Python312\site-packages\django\core\handlers\base.py", line 197, in _get_response
    response = wrapped_callback(request, *callback_args, **callback_kwargs)
               ^^^^^^^^^^^^^^^^^^^^^^^^^^^^^^^^^^^^^^^^^^^^^^^^^^^^^^^^^^^^
  File "C:\Users\Spero\AppData\Roaming\Python\Python312\site-packages\django\views\decorators\csrf.py", line 65, in _view_wrapper
    return view_func(request, *args, **kwargs)
           ^^^^^^^^^^^^^^^^^^^^^^^^^^^^^^^^^^^
  File "C:\Users\Spero\AppData\Roaming\Python\Python312\site-packages\django\views\generic\base.py", line 104, in view
    return self.dispatch(request, *args, **kwargs)
           ^^^^^^^^^^^^^^^^^^^^^^^^^^^^^^^^^^^^^^^
  File "C:\Users\Spero\AppData\Roaming\Python\Python312\site-packages\rest_framework\views.py", line 515, in dispatch
    response = self.handle_exception(exc)
               ^^^^^^^^^^^^^^^^^^^^^^^^^^
  File "C:\Users\Spero\AppData\Roaming\Python\Python312\site-packages\rest_framework\views.py", line 475, in handle_exception
    self.raise_uncaught_exception(exc)
  File "C:\Users\Spero\AppData\Roaming\Python\Python312\site-packages\rest_framework\views.py", line 486, in raise_uncaught_exception
    raise exc
  File "C:\Users\Spero\AppData\Roaming\Python\Python312\site-packages\rest_framework\views.py", line 512, in dispatch
    response = handler(request, *args, **kwargs)
               ^^^^^^^^^^^^^^^^^^^^^^^^^^^^^^^^^
  File "C:\Spero\Spero-DMS\DMS_goa\admin_web\views.py", line 256, in get
    new_captcha = CaptchaStore.generate_key()
                  ^^^^^^^^^^^^^^^^^^^^^^^^^^^
  File "C:\Users\Spero\AppData\Roaming\Python\Python312\site-packages\captcha\models.py", line 60, in generate_key
    store = cls.objects.create(challenge=challenge, response=response)
            ^^^^^^^^^^^^^^^^^^^^^^^^^^^^^^^^^^^^^^^^^^^^^^^^^^^^^^^^^^
  File "C:\Users\Spero\AppData\Roaming\Python\Python312\site-packages\django\db\models\manager.py", line 87, in manager_method
    return getattr(self.get_queryset(), name)(*args, **kwargs)
           ^^^^^^^^^^^^^^^^^^^^^^^^^^^^^^^^^^^^^^^^^^^^^^^^^^^
  File "C:\Users\Spero\AppData\Roaming\Python\Python312\site-packages\django\db\models\query.py", line 663, in create
    obj.save(force_insert=True, using=self.db)
  File "C:\Users\Spero\AppData\Roaming\Python\Python312\site-packages\captcha\models.py", line 47, in save
    super().save(*args, **kwargs)
  File "C:\Users\Spero\AppData\Roaming\Python\Python312\site-packages\django\db\models\base.py", line 902, in save
    self.save_base(
  File "C:\Users\Spero\AppData\Roaming\Python\Python312\site-packages\django\db\models\base.py", line 1008, in save_base
    updated = self._save_table(
              ^^^^^^^^^^^^^^^^^
  File "C:\Users\Spero\AppData\Roaming\Python\Python312\site-packages\django\db\models\base.py", line 1169, in _save_table
    results = self._do_insert(
              ^^^^^^^^^^^^^^^^
  File "C:\Users\Spero\AppData\Roaming\Python\Python312\site-packages\django\db\models\base.py", line 1210, in _do_insert
    return manager._insert(
           ^^^^^^^^^^^^^^^^
  File "C:\Users\Spero\AppData\Roaming\Python\Python312\site-packages\django\db\models\manager.py", line 87, in manager_method
    return getattr(self.get_queryset(), name)(*args, **kwargs)
           ^^^^^^^^^^^^^^^^^^^^^^^^^^^^^^^^^^^^^^^^^^^^^^^^^^^
  File "C:\Users\Spero\AppData\Roaming\Python\Python312\site-packages\django\db\models\query.py", line 1864, in _insert
    return query.get_compiler(using=using).execute_sql(returning_fields)
           ^^^^^^^^^^^^^^^^^^^^^^^^^^^^^^^^^^^^^^^^^^^^^^^^^^^^^^^^^^^^^
  File "C:\Users\Spero\AppData\Roaming\Python\Python312\site-packages\django\db\models\sql\compiler.py", line 1880, in execute_sql
    with self.connection.cursor() as cursor:
         ^^^^^^^^^^^^^^^^^^^^^^^^
  File "C:\Users\Spero\AppData\Roaming\Python\Python312\site-packages\django\utils\asyncio.py", line 26, in inner
    return func(*args, **kwargs)
           ^^^^^^^^^^^^^^^^^^^^^
  File "C:\Users\Spero\AppData\Roaming\Python\Python312\site-packages\django\db\backends\base\base.py", line 320, in cursor
    return self._cursor()
           ^^^^^^^^^^^^^^
  File "C:\Users\Spero\AppData\Roaming\Python\Python312\site-packages\django\db\backends\base\base.py", line 296, in _cursor
    self.ensure_connection()
  File "C:\Users\Spero\AppData\Roaming\Python\Python312\site-packages\django\utils\asyncio.py", line 26, in inner
    return func(*args, **kwargs)
           ^^^^^^^^^^^^^^^^^^^^^
  File "C:\Users\Spero\AppData\Roaming\Python\Python312\site-packages\django\db\backends\base\base.py", line 278, in ensure_connection
    with self.wrap_database_errors:
         ^^^^^^^^^^^^^^^^^^^^^^^^^
  File "C:\Users\Spero\AppData\Roaming\Python\Python312\site-packages\django\db\utils.py", line 91, in __exit__
    raise dj_exc_value.with_traceback(traceback) from exc_value
  File "C:\Users\Spero\AppData\Roaming\Python\Python312\site-packages\django\db\backends\base\base.py", line 279, in ensure_connection
    self.connect()
  File "C:\Users\Spero\AppData\Roaming\Python\Python312\site-packages\django\utils\asyncio.py", line 26, in inner
    return func(*args, **kwargs)
           ^^^^^^^^^^^^^^^^^^^^^
  File "C:\Users\Spero\AppData\Roaming\Python\Python312\site-packages\django\db\backends\base\base.py", line 256, in connect
    self.connection = self.get_new_connection(conn_params)
                      ^^^^^^^^^^^^^^^^^^^^^^^^^^^^^^^^^^^^
  File "C:\Users\Spero\AppData\Roaming\Python\Python312\site-packages\django\utils\asyncio.py", line 26, in inner
    return func(*args, **kwargs)
           ^^^^^^^^^^^^^^^^^^^^^
  File "C:\Users\Spero\AppData\Roaming\Python\Python312\site-packages\django\db\backends\postgresql\base.py", line 332, in get_new_connection
    connection = self.Database.connect(**conn_params)
                 ^^^^^^^^^^^^^^^^^^^^^^^^^^^^^^^^^^^^
  File "C:\Users\Spero\AppData\Roaming\Python\Python312\site-packages\psycopg2\__init__.py", line 122, in connect
    conn = _connect(dsn, connection_factory=connection_factory, **kwasync)
           ^^^^^^^^^^^^^^^^^^^^^^^^^^^^^^^^^^^^^^^^^^^^^^^^^^^^^^^^^^^^^^^
django.db.utils.OperationalError: connection to server at "192.168.1.116", port 5432 failed: No route to host (0x00002751/10065)
	Is the server running on that host and accepting TCP/IP connections?

ERROR 2025-05-14 16:04:12,215 basehttp "GET /admin_web/login/captcha/ HTTP/1.1" 500 229232
ERROR 2025-05-14 17:55:27,481 log Internal Server Error: /admin_web/login/captcha/
Traceback (most recent call last):
  File "C:\Users\Spero\AppData\Roaming\Python\Python312\site-packages\django\db\backends\base\base.py", line 279, in ensure_connection
    self.connect()
  File "C:\Users\Spero\AppData\Roaming\Python\Python312\site-packages\django\utils\asyncio.py", line 26, in inner
    return func(*args, **kwargs)
           ^^^^^^^^^^^^^^^^^^^^^
  File "C:\Users\Spero\AppData\Roaming\Python\Python312\site-packages\django\db\backends\base\base.py", line 256, in connect
    self.connection = self.get_new_connection(conn_params)
                      ^^^^^^^^^^^^^^^^^^^^^^^^^^^^^^^^^^^^
  File "C:\Users\Spero\AppData\Roaming\Python\Python312\site-packages\django\utils\asyncio.py", line 26, in inner
    return func(*args, **kwargs)
           ^^^^^^^^^^^^^^^^^^^^^
  File "C:\Users\Spero\AppData\Roaming\Python\Python312\site-packages\django\db\backends\postgresql\base.py", line 332, in get_new_connection
    connection = self.Database.connect(**conn_params)
                 ^^^^^^^^^^^^^^^^^^^^^^^^^^^^^^^^^^^^
  File "C:\Users\Spero\AppData\Roaming\Python\Python312\site-packages\psycopg2\__init__.py", line 122, in connect
    conn = _connect(dsn, connection_factory=connection_factory, **kwasync)
           ^^^^^^^^^^^^^^^^^^^^^^^^^^^^^^^^^^^^^^^^^^^^^^^^^^^^^^^^^^^^^^^
psycopg2.OperationalError: connection to server at "192.168.1.116", port 5432 failed: No route to host (0x00002751/10065)
	Is the server running on that host and accepting TCP/IP connections?


The above exception was the direct cause of the following exception:

Traceback (most recent call last):
  File "C:\Users\Spero\AppData\Roaming\Python\Python312\site-packages\django\core\handlers\exception.py", line 55, in inner
    response = get_response(request)
               ^^^^^^^^^^^^^^^^^^^^^
  File "C:\Users\Spero\AppData\Roaming\Python\Python312\site-packages\django\core\handlers\base.py", line 197, in _get_response
    response = wrapped_callback(request, *callback_args, **callback_kwargs)
               ^^^^^^^^^^^^^^^^^^^^^^^^^^^^^^^^^^^^^^^^^^^^^^^^^^^^^^^^^^^^
  File "C:\Users\Spero\AppData\Roaming\Python\Python312\site-packages\django\views\decorators\csrf.py", line 65, in _view_wrapper
    return view_func(request, *args, **kwargs)
           ^^^^^^^^^^^^^^^^^^^^^^^^^^^^^^^^^^^
  File "C:\Users\Spero\AppData\Roaming\Python\Python312\site-packages\django\views\generic\base.py", line 104, in view
    return self.dispatch(request, *args, **kwargs)
           ^^^^^^^^^^^^^^^^^^^^^^^^^^^^^^^^^^^^^^^
  File "C:\Users\Spero\AppData\Roaming\Python\Python312\site-packages\rest_framework\views.py", line 515, in dispatch
    response = self.handle_exception(exc)
               ^^^^^^^^^^^^^^^^^^^^^^^^^^
  File "C:\Users\Spero\AppData\Roaming\Python\Python312\site-packages\rest_framework\views.py", line 475, in handle_exception
    self.raise_uncaught_exception(exc)
  File "C:\Users\Spero\AppData\Roaming\Python\Python312\site-packages\rest_framework\views.py", line 486, in raise_uncaught_exception
    raise exc
  File "C:\Users\Spero\AppData\Roaming\Python\Python312\site-packages\rest_framework\views.py", line 512, in dispatch
    response = handler(request, *args, **kwargs)
               ^^^^^^^^^^^^^^^^^^^^^^^^^^^^^^^^^
  File "C:\Spero\Spero-DMS\DMS_goa\admin_web\views.py", line 256, in get
    new_captcha = CaptchaStore.generate_key()
                  ^^^^^^^^^^^^^^^^^^^^^^^^^^^
  File "C:\Users\Spero\AppData\Roaming\Python\Python312\site-packages\captcha\models.py", line 60, in generate_key
    store = cls.objects.create(challenge=challenge, response=response)
            ^^^^^^^^^^^^^^^^^^^^^^^^^^^^^^^^^^^^^^^^^^^^^^^^^^^^^^^^^^
  File "C:\Users\Spero\AppData\Roaming\Python\Python312\site-packages\django\db\models\manager.py", line 87, in manager_method
    return getattr(self.get_queryset(), name)(*args, **kwargs)
           ^^^^^^^^^^^^^^^^^^^^^^^^^^^^^^^^^^^^^^^^^^^^^^^^^^^
  File "C:\Users\Spero\AppData\Roaming\Python\Python312\site-packages\django\db\models\query.py", line 663, in create
    obj.save(force_insert=True, using=self.db)
  File "C:\Users\Spero\AppData\Roaming\Python\Python312\site-packages\captcha\models.py", line 47, in save
    super().save(*args, **kwargs)
  File "C:\Users\Spero\AppData\Roaming\Python\Python312\site-packages\django\db\models\base.py", line 902, in save
    self.save_base(
  File "C:\Users\Spero\AppData\Roaming\Python\Python312\site-packages\django\db\models\base.py", line 1008, in save_base
    updated = self._save_table(
              ^^^^^^^^^^^^^^^^^
  File "C:\Users\Spero\AppData\Roaming\Python\Python312\site-packages\django\db\models\base.py", line 1169, in _save_table
    results = self._do_insert(
              ^^^^^^^^^^^^^^^^
  File "C:\Users\Spero\AppData\Roaming\Python\Python312\site-packages\django\db\models\base.py", line 1210, in _do_insert
    return manager._insert(
           ^^^^^^^^^^^^^^^^
  File "C:\Users\Spero\AppData\Roaming\Python\Python312\site-packages\django\db\models\manager.py", line 87, in manager_method
    return getattr(self.get_queryset(), name)(*args, **kwargs)
           ^^^^^^^^^^^^^^^^^^^^^^^^^^^^^^^^^^^^^^^^^^^^^^^^^^^
  File "C:\Users\Spero\AppData\Roaming\Python\Python312\site-packages\django\db\models\query.py", line 1864, in _insert
    return query.get_compiler(using=using).execute_sql(returning_fields)
           ^^^^^^^^^^^^^^^^^^^^^^^^^^^^^^^^^^^^^^^^^^^^^^^^^^^^^^^^^^^^^
  File "C:\Users\Spero\AppData\Roaming\Python\Python312\site-packages\django\db\models\sql\compiler.py", line 1880, in execute_sql
    with self.connection.cursor() as cursor:
         ^^^^^^^^^^^^^^^^^^^^^^^^
  File "C:\Users\Spero\AppData\Roaming\Python\Python312\site-packages\django\utils\asyncio.py", line 26, in inner
    return func(*args, **kwargs)
           ^^^^^^^^^^^^^^^^^^^^^
  File "C:\Users\Spero\AppData\Roaming\Python\Python312\site-packages\django\db\backends\base\base.py", line 320, in cursor
    return self._cursor()
           ^^^^^^^^^^^^^^
  File "C:\Users\Spero\AppData\Roaming\Python\Python312\site-packages\django\db\backends\base\base.py", line 296, in _cursor
    self.ensure_connection()
  File "C:\Users\Spero\AppData\Roaming\Python\Python312\site-packages\django\utils\asyncio.py", line 26, in inner
    return func(*args, **kwargs)
           ^^^^^^^^^^^^^^^^^^^^^
  File "C:\Users\Spero\AppData\Roaming\Python\Python312\site-packages\django\db\backends\base\base.py", line 278, in ensure_connection
    with self.wrap_database_errors:
         ^^^^^^^^^^^^^^^^^^^^^^^^^
  File "C:\Users\Spero\AppData\Roaming\Python\Python312\site-packages\django\db\utils.py", line 91, in __exit__
    raise dj_exc_value.with_traceback(traceback) from exc_value
  File "C:\Users\Spero\AppData\Roaming\Python\Python312\site-packages\django\db\backends\base\base.py", line 279, in ensure_connection
    self.connect()
  File "C:\Users\Spero\AppData\Roaming\Python\Python312\site-packages\django\utils\asyncio.py", line 26, in inner
    return func(*args, **kwargs)
           ^^^^^^^^^^^^^^^^^^^^^
  File "C:\Users\Spero\AppData\Roaming\Python\Python312\site-packages\django\db\backends\base\base.py", line 256, in connect
    self.connection = self.get_new_connection(conn_params)
                      ^^^^^^^^^^^^^^^^^^^^^^^^^^^^^^^^^^^^
  File "C:\Users\Spero\AppData\Roaming\Python\Python312\site-packages\django\utils\asyncio.py", line 26, in inner
    return func(*args, **kwargs)
           ^^^^^^^^^^^^^^^^^^^^^
  File "C:\Users\Spero\AppData\Roaming\Python\Python312\site-packages\django\db\backends\postgresql\base.py", line 332, in get_new_connection
    connection = self.Database.connect(**conn_params)
                 ^^^^^^^^^^^^^^^^^^^^^^^^^^^^^^^^^^^^
  File "C:\Users\Spero\AppData\Roaming\Python\Python312\site-packages\psycopg2\__init__.py", line 122, in connect
    conn = _connect(dsn, connection_factory=connection_factory, **kwasync)
           ^^^^^^^^^^^^^^^^^^^^^^^^^^^^^^^^^^^^^^^^^^^^^^^^^^^^^^^^^^^^^^^
django.db.utils.OperationalError: connection to server at "192.168.1.116", port 5432 failed: No route to host (0x00002751/10065)
	Is the server running on that host and accepting TCP/IP connections?

ERROR 2025-05-14 17:55:27,509 basehttp "GET /admin_web/login/captcha/ HTTP/1.1" 500 229232
ERROR 2025-05-14 17:55:28,017 log Internal Server Error: /admin_web/login/captcha/
Traceback (most recent call last):
  File "C:\Users\Spero\AppData\Roaming\Python\Python312\site-packages\django\db\backends\base\base.py", line 279, in ensure_connection
    self.connect()
  File "C:\Users\Spero\AppData\Roaming\Python\Python312\site-packages\django\utils\asyncio.py", line 26, in inner
    return func(*args, **kwargs)
           ^^^^^^^^^^^^^^^^^^^^^
  File "C:\Users\Spero\AppData\Roaming\Python\Python312\site-packages\django\db\backends\base\base.py", line 256, in connect
    self.connection = self.get_new_connection(conn_params)
                      ^^^^^^^^^^^^^^^^^^^^^^^^^^^^^^^^^^^^
  File "C:\Users\Spero\AppData\Roaming\Python\Python312\site-packages\django\utils\asyncio.py", line 26, in inner
    return func(*args, **kwargs)
           ^^^^^^^^^^^^^^^^^^^^^
  File "C:\Users\Spero\AppData\Roaming\Python\Python312\site-packages\django\db\backends\postgresql\base.py", line 332, in get_new_connection
    connection = self.Database.connect(**conn_params)
                 ^^^^^^^^^^^^^^^^^^^^^^^^^^^^^^^^^^^^
  File "C:\Users\Spero\AppData\Roaming\Python\Python312\site-packages\psycopg2\__init__.py", line 122, in connect
    conn = _connect(dsn, connection_factory=connection_factory, **kwasync)
           ^^^^^^^^^^^^^^^^^^^^^^^^^^^^^^^^^^^^^^^^^^^^^^^^^^^^^^^^^^^^^^^
psycopg2.OperationalError: connection to server at "192.168.1.116", port 5432 failed: No route to host (0x00002751/10065)
	Is the server running on that host and accepting TCP/IP connections?


The above exception was the direct cause of the following exception:

Traceback (most recent call last):
  File "C:\Users\Spero\AppData\Roaming\Python\Python312\site-packages\django\core\handlers\exception.py", line 55, in inner
    response = get_response(request)
               ^^^^^^^^^^^^^^^^^^^^^
  File "C:\Users\Spero\AppData\Roaming\Python\Python312\site-packages\django\core\handlers\base.py", line 197, in _get_response
    response = wrapped_callback(request, *callback_args, **callback_kwargs)
               ^^^^^^^^^^^^^^^^^^^^^^^^^^^^^^^^^^^^^^^^^^^^^^^^^^^^^^^^^^^^
  File "C:\Users\Spero\AppData\Roaming\Python\Python312\site-packages\django\views\decorators\csrf.py", line 65, in _view_wrapper
    return view_func(request, *args, **kwargs)
           ^^^^^^^^^^^^^^^^^^^^^^^^^^^^^^^^^^^
  File "C:\Users\Spero\AppData\Roaming\Python\Python312\site-packages\django\views\generic\base.py", line 104, in view
    return self.dispatch(request, *args, **kwargs)
           ^^^^^^^^^^^^^^^^^^^^^^^^^^^^^^^^^^^^^^^
  File "C:\Users\Spero\AppData\Roaming\Python\Python312\site-packages\rest_framework\views.py", line 515, in dispatch
    response = self.handle_exception(exc)
               ^^^^^^^^^^^^^^^^^^^^^^^^^^
  File "C:\Users\Spero\AppData\Roaming\Python\Python312\site-packages\rest_framework\views.py", line 475, in handle_exception
    self.raise_uncaught_exception(exc)
  File "C:\Users\Spero\AppData\Roaming\Python\Python312\site-packages\rest_framework\views.py", line 486, in raise_uncaught_exception
    raise exc
  File "C:\Users\Spero\AppData\Roaming\Python\Python312\site-packages\rest_framework\views.py", line 512, in dispatch
    response = handler(request, *args, **kwargs)
               ^^^^^^^^^^^^^^^^^^^^^^^^^^^^^^^^^
  File "C:\Spero\Spero-DMS\DMS_goa\admin_web\views.py", line 256, in get
    new_captcha = CaptchaStore.generate_key()
                  ^^^^^^^^^^^^^^^^^^^^^^^^^^^
  File "C:\Users\Spero\AppData\Roaming\Python\Python312\site-packages\captcha\models.py", line 60, in generate_key
    store = cls.objects.create(challenge=challenge, response=response)
            ^^^^^^^^^^^^^^^^^^^^^^^^^^^^^^^^^^^^^^^^^^^^^^^^^^^^^^^^^^
  File "C:\Users\Spero\AppData\Roaming\Python\Python312\site-packages\django\db\models\manager.py", line 87, in manager_method
    return getattr(self.get_queryset(), name)(*args, **kwargs)
           ^^^^^^^^^^^^^^^^^^^^^^^^^^^^^^^^^^^^^^^^^^^^^^^^^^^
  File "C:\Users\Spero\AppData\Roaming\Python\Python312\site-packages\django\db\models\query.py", line 663, in create
    obj.save(force_insert=True, using=self.db)
  File "C:\Users\Spero\AppData\Roaming\Python\Python312\site-packages\captcha\models.py", line 47, in save
    super().save(*args, **kwargs)
  File "C:\Users\Spero\AppData\Roaming\Python\Python312\site-packages\django\db\models\base.py", line 902, in save
    self.save_base(
  File "C:\Users\Spero\AppData\Roaming\Python\Python312\site-packages\django\db\models\base.py", line 1008, in save_base
    updated = self._save_table(
              ^^^^^^^^^^^^^^^^^
  File "C:\Users\Spero\AppData\Roaming\Python\Python312\site-packages\django\db\models\base.py", line 1169, in _save_table
    results = self._do_insert(
              ^^^^^^^^^^^^^^^^
  File "C:\Users\Spero\AppData\Roaming\Python\Python312\site-packages\django\db\models\base.py", line 1210, in _do_insert
    return manager._insert(
           ^^^^^^^^^^^^^^^^
  File "C:\Users\Spero\AppData\Roaming\Python\Python312\site-packages\django\db\models\manager.py", line 87, in manager_method
    return getattr(self.get_queryset(), name)(*args, **kwargs)
           ^^^^^^^^^^^^^^^^^^^^^^^^^^^^^^^^^^^^^^^^^^^^^^^^^^^
  File "C:\Users\Spero\AppData\Roaming\Python\Python312\site-packages\django\db\models\query.py", line 1864, in _insert
    return query.get_compiler(using=using).execute_sql(returning_fields)
           ^^^^^^^^^^^^^^^^^^^^^^^^^^^^^^^^^^^^^^^^^^^^^^^^^^^^^^^^^^^^^
  File "C:\Users\Spero\AppData\Roaming\Python\Python312\site-packages\django\db\models\sql\compiler.py", line 1880, in execute_sql
    with self.connection.cursor() as cursor:
         ^^^^^^^^^^^^^^^^^^^^^^^^
  File "C:\Users\Spero\AppData\Roaming\Python\Python312\site-packages\django\utils\asyncio.py", line 26, in inner
    return func(*args, **kwargs)
           ^^^^^^^^^^^^^^^^^^^^^
  File "C:\Users\Spero\AppData\Roaming\Python\Python312\site-packages\django\db\backends\base\base.py", line 320, in cursor
    return self._cursor()
           ^^^^^^^^^^^^^^
  File "C:\Users\Spero\AppData\Roaming\Python\Python312\site-packages\django\db\backends\base\base.py", line 296, in _cursor
    self.ensure_connection()
  File "C:\Users\Spero\AppData\Roaming\Python\Python312\site-packages\django\utils\asyncio.py", line 26, in inner
    return func(*args, **kwargs)
           ^^^^^^^^^^^^^^^^^^^^^
  File "C:\Users\Spero\AppData\Roaming\Python\Python312\site-packages\django\db\backends\base\base.py", line 278, in ensure_connection
    with self.wrap_database_errors:
         ^^^^^^^^^^^^^^^^^^^^^^^^^
  File "C:\Users\Spero\AppData\Roaming\Python\Python312\site-packages\django\db\utils.py", line 91, in __exit__
    raise dj_exc_value.with_traceback(traceback) from exc_value
  File "C:\Users\Spero\AppData\Roaming\Python\Python312\site-packages\django\db\backends\base\base.py", line 279, in ensure_connection
    self.connect()
  File "C:\Users\Spero\AppData\Roaming\Python\Python312\site-packages\django\utils\asyncio.py", line 26, in inner
    return func(*args, **kwargs)
           ^^^^^^^^^^^^^^^^^^^^^
  File "C:\Users\Spero\AppData\Roaming\Python\Python312\site-packages\django\db\backends\base\base.py", line 256, in connect
    self.connection = self.get_new_connection(conn_params)
                      ^^^^^^^^^^^^^^^^^^^^^^^^^^^^^^^^^^^^
  File "C:\Users\Spero\AppData\Roaming\Python\Python312\site-packages\django\utils\asyncio.py", line 26, in inner
    return func(*args, **kwargs)
           ^^^^^^^^^^^^^^^^^^^^^
  File "C:\Users\Spero\AppData\Roaming\Python\Python312\site-packages\django\db\backends\postgresql\base.py", line 332, in get_new_connection
    connection = self.Database.connect(**conn_params)
                 ^^^^^^^^^^^^^^^^^^^^^^^^^^^^^^^^^^^^
  File "C:\Users\Spero\AppData\Roaming\Python\Python312\site-packages\psycopg2\__init__.py", line 122, in connect
    conn = _connect(dsn, connection_factory=connection_factory, **kwasync)
           ^^^^^^^^^^^^^^^^^^^^^^^^^^^^^^^^^^^^^^^^^^^^^^^^^^^^^^^^^^^^^^^
django.db.utils.OperationalError: connection to server at "192.168.1.116", port 5432 failed: No route to host (0x00002751/10065)
	Is the server running on that host and accepting TCP/IP connections?

ERROR 2025-05-14 17:55:28,048 basehttp "GET /admin_web/login/captcha/ HTTP/1.1" 500 229232
WARNING 2025-05-14 17:57:03,705 log Bad Request: /admin_web/login/
WARNING 2025-05-14 17:57:03,707 basehttp "POST /admin_web/login/ HTTP/1.1" 400 58
WARNING 2025-05-14 18:01:54,212 log Bad Request: /admin_web/login/
WARNING 2025-05-14 18:01:54,219 basehttp "POST /admin_web/login/ HTTP/1.1" 400 58
WARNING 2025-05-14 18:02:02,479 log Bad Request: /admin_web/login/
WARNING 2025-05-14 18:02:02,482 basehttp "POST /admin_web/login/ HTTP/1.1" 400 54
WARNING 2025-05-14 18:02:44,994 log Bad Request: /admin_web/login/
WARNING 2025-05-14 18:02:44,997 basehttp "POST /admin_web/login/ HTTP/1.1" 400 58
WARNING 2025-05-15 11:51:55,220 log Bad Request: /admin_web/login/
WARNING 2025-05-15 11:51:55,223 basehttp "POST /admin_web/login/ HTTP/1.1" 400 54
WARNING 2025-05-15 12:22:00,559 log Bad Request: /admin_web/login/
WARNING 2025-05-15 12:22:00,562 basehttp "POST /admin_web/login/ HTTP/1.1" 400 54
WARNING 2025-05-15 12:23:52,763 log Bad Request: /admin_web/login/
WARNING 2025-05-15 12:23:52,766 basehttp "POST /admin_web/login/ HTTP/1.1" 400 58
WARNING 2025-05-15 12:24:02,960 log Bad Request: /admin_web/login/
WARNING 2025-05-15 12:24:02,962 basehttp "POST /admin_web/login/ HTTP/1.1" 400 54
WARNING 2025-05-15 12:33:38,109 log Unauthorized: /admin_web/login/
WARNING 2025-05-15 12:33:38,110 basehttp "POST /admin_web/login/ HTTP/1.1" 401 76
WARNING 2025-05-16 14:29:24,076 log Unauthorized: /admin_web/district_get/
WARNING 2025-05-16 14:29:24,079 log Unauthorized: /admin_web/Tahsil_get/
WARNING 2025-05-16 14:29:24,083 basehttp "GET /admin_web/Tahsil_get/ HTTP/1.1" 401 172
WARNING 2025-05-16 14:29:24,088 basehttp "GET /admin_web/district_get/ HTTP/1.1" 401 172
WARNING 2025-05-16 14:29:24,163 log Unauthorized: /admin_web/Tahsil_get/
WARNING 2025-05-16 14:29:24,168 log Unauthorized: /admin_web/district_get/
WARNING 2025-05-16 14:29:24,170 basehttp "GET /admin_web/Tahsil_get/ HTTP/1.1" 401 172
WARNING 2025-05-16 14:29:24,172 basehttp "GET /admin_web/district_get/ HTTP/1.1" 401 172
WARNING 2025-05-16 14:29:38,015 log Bad Request: /admin_web/login/
WARNING 2025-05-16 14:29:38,015 basehttp "POST /admin_web/login/ HTTP/1.1" 400 54
ERROR 2025-05-16 14:47:50,195 log Internal Server Error: /admin_web/district_get/
Traceback (most recent call last):
  File "C:\Users\Spero 70\AppData\Local\Programs\Python\Python311\Lib\site-packages\django\db\backends\base\base.py", line 279, in ensure_connection
    self.connect()
  File "C:\Users\Spero 70\AppData\Local\Programs\Python\Python311\Lib\site-packages\django\utils\asyncio.py", line 26, in inner
    return func(*args, **kwargs)
           ^^^^^^^^^^^^^^^^^^^^^
  File "C:\Users\Spero 70\AppData\Local\Programs\Python\Python311\Lib\site-packages\django\db\backends\base\base.py", line 256, in connect
    self.connection = self.get_new_connection(conn_params)
                      ^^^^^^^^^^^^^^^^^^^^^^^^^^^^^^^^^^^^
  File "C:\Users\Spero 70\AppData\Local\Programs\Python\Python311\Lib\site-packages\django\utils\asyncio.py", line 26, in inner
    return func(*args, **kwargs)
           ^^^^^^^^^^^^^^^^^^^^^
  File "C:\Users\Spero 70\AppData\Local\Programs\Python\Python311\Lib\site-packages\django\db\backends\postgresql\base.py", line 332, in get_new_connection
    connection = self.Database.connect(**conn_params)
                 ^^^^^^^^^^^^^^^^^^^^^^^^^^^^^^^^^^^^
  File "C:\Users\Spero 70\AppData\Local\Programs\Python\Python311\Lib\site-packages\psycopg2\__init__.py", line 122, in connect
    conn = _connect(dsn, connection_factory=connection_factory, **kwasync)
           ^^^^^^^^^^^^^^^^^^^^^^^^^^^^^^^^^^^^^^^^^^^^^^^^^^^^^^^^^^^^^^^
psycopg2.OperationalError: connection to server at "122.176.232.35", port 5433 failed: FATAL:  sorry, too many clients already
connection to server at "122.176.232.35", port 5433 failed: FATAL:  sorry, too many clients already


The above exception was the direct cause of the following exception:

Traceback (most recent call last):
  File "C:\Users\Spero 70\AppData\Local\Programs\Python\Python311\Lib\site-packages\django\core\handlers\exception.py", line 55, in inner
    response = get_response(request)
               ^^^^^^^^^^^^^^^^^^^^^
  File "C:\Users\Spero 70\AppData\Local\Programs\Python\Python311\Lib\site-packages\django\core\handlers\base.py", line 197, in _get_response
    response = wrapped_callback(request, *callback_args, **callback_kwargs)
               ^^^^^^^^^^^^^^^^^^^^^^^^^^^^^^^^^^^^^^^^^^^^^^^^^^^^^^^^^^^^
  File "C:\Users\Spero 70\AppData\Local\Programs\Python\Python311\Lib\site-packages\django\views\decorators\csrf.py", line 65, in _view_wrapper
    return view_func(request, *args, **kwargs)
           ^^^^^^^^^^^^^^^^^^^^^^^^^^^^^^^^^^^
  File "C:\Users\Spero 70\AppData\Local\Programs\Python\Python311\Lib\site-packages\django\views\generic\base.py", line 104, in view
    return self.dispatch(request, *args, **kwargs)
           ^^^^^^^^^^^^^^^^^^^^^^^^^^^^^^^^^^^^^^^
  File "C:\Users\Spero 70\AppData\Local\Programs\Python\Python311\Lib\site-packages\rest_framework\views.py", line 515, in dispatch
    response = self.handle_exception(exc)
               ^^^^^^^^^^^^^^^^^^^^^^^^^^
  File "C:\Users\Spero 70\AppData\Local\Programs\Python\Python311\Lib\site-packages\rest_framework\views.py", line 475, in handle_exception
    self.raise_uncaught_exception(exc)
  File "C:\Users\Spero 70\AppData\Local\Programs\Python\Python311\Lib\site-packages\rest_framework\views.py", line 486, in raise_uncaught_exception
    raise exc
  File "C:\Users\Spero 70\AppData\Local\Programs\Python\Python311\Lib\site-packages\rest_framework\views.py", line 503, in dispatch
    self.initial(request, *args, **kwargs)
  File "C:\Users\Spero 70\AppData\Local\Programs\Python\Python311\Lib\site-packages\rest_framework\views.py", line 420, in initial
    self.perform_authentication(request)
  File "C:\Users\Spero 70\AppData\Local\Programs\Python\Python311\Lib\site-packages\rest_framework\views.py", line 330, in perform_authentication
    request.user
  File "C:\Users\Spero 70\AppData\Local\Programs\Python\Python311\Lib\site-packages\rest_framework\request.py", line 232, in user
    self._authenticate()
  File "C:\Users\Spero 70\AppData\Local\Programs\Python\Python311\Lib\site-packages\rest_framework\request.py", line 385, in _authenticate
    user_auth_tuple = authenticator.authenticate(self)
                      ^^^^^^^^^^^^^^^^^^^^^^^^^^^^^^^^
  File "C:\Users\Spero 70\AppData\Local\Programs\Python\Python311\Lib\site-packages\rest_framework_simplejwt\authentication.py", line 51, in authenticate
    return self.get_user(validated_token), validated_token
           ^^^^^^^^^^^^^^^^^^^^^^^^^^^^^^
  File "C:\Users\Spero 70\AppData\Local\Programs\Python\Python311\Lib\site-packages\rest_framework_simplejwt\authentication.py", line 130, in get_user
    user = self.user_model.objects.get(**{api_settings.USER_ID_FIELD: user_id})
           ^^^^^^^^^^^^^^^^^^^^^^^^^^^^^^^^^^^^^^^^^^^^^^^^^^^^^^^^^^^^^^^^^^^^
  File "C:\Users\Spero 70\AppData\Local\Programs\Python\Python311\Lib\site-packages\django\db\models\manager.py", line 87, in manager_method
    return getattr(self.get_queryset(), name)(*args, **kwargs)
           ^^^^^^^^^^^^^^^^^^^^^^^^^^^^^^^^^^^^^^^^^^^^^^^^^^^
  File "C:\Users\Spero 70\AppData\Local\Programs\Python\Python311\Lib\site-packages\django\db\models\query.py", line 629, in get
    num = len(clone)
          ^^^^^^^^^^
  File "C:\Users\Spero 70\AppData\Local\Programs\Python\Python311\Lib\site-packages\django\db\models\query.py", line 366, in __len__
    self._fetch_all()
  File "C:\Users\Spero 70\AppData\Local\Programs\Python\Python311\Lib\site-packages\django\db\models\query.py", line 1935, in _fetch_all
    self._result_cache = list(self._iterable_class(self))
                         ^^^^^^^^^^^^^^^^^^^^^^^^^^^^^^^^
  File "C:\Users\Spero 70\AppData\Local\Programs\Python\Python311\Lib\site-packages\django\db\models\query.py", line 91, in __iter__
    results = compiler.execute_sql(
              ^^^^^^^^^^^^^^^^^^^^^
  File "C:\Users\Spero 70\AppData\Local\Programs\Python\Python311\Lib\site-packages\django\db\models\sql\compiler.py", line 1620, in execute_sql
    cursor = self.connection.cursor()
             ^^^^^^^^^^^^^^^^^^^^^^^^
  File "C:\Users\Spero 70\AppData\Local\Programs\Python\Python311\Lib\site-packages\django\utils\asyncio.py", line 26, in inner
    return func(*args, **kwargs)
           ^^^^^^^^^^^^^^^^^^^^^
  File "C:\Users\Spero 70\AppData\Local\Programs\Python\Python311\Lib\site-packages\django\db\backends\base\base.py", line 320, in cursor
    return self._cursor()
           ^^^^^^^^^^^^^^
  File "C:\Users\Spero 70\AppData\Local\Programs\Python\Python311\Lib\site-packages\django\db\backends\base\base.py", line 296, in _cursor
    self.ensure_connection()
  File "C:\Users\Spero 70\AppData\Local\Programs\Python\Python311\Lib\site-packages\django\utils\asyncio.py", line 26, in inner
    return func(*args, **kwargs)
           ^^^^^^^^^^^^^^^^^^^^^
  File "C:\Users\Spero 70\AppData\Local\Programs\Python\Python311\Lib\site-packages\django\db\backends\base\base.py", line 278, in ensure_connection
    with self.wrap_database_errors:
  File "C:\Users\Spero 70\AppData\Local\Programs\Python\Python311\Lib\site-packages\django\db\utils.py", line 91, in __exit__
    raise dj_exc_value.with_traceback(traceback) from exc_value
  File "C:\Users\Spero 70\AppData\Local\Programs\Python\Python311\Lib\site-packages\django\db\backends\base\base.py", line 279, in ensure_connection
    self.connect()
  File "C:\Users\Spero 70\AppData\Local\Programs\Python\Python311\Lib\site-packages\django\utils\asyncio.py", line 26, in inner
    return func(*args, **kwargs)
           ^^^^^^^^^^^^^^^^^^^^^
  File "C:\Users\Spero 70\AppData\Local\Programs\Python\Python311\Lib\site-packages\django\db\backends\base\base.py", line 256, in connect
    self.connection = self.get_new_connection(conn_params)
                      ^^^^^^^^^^^^^^^^^^^^^^^^^^^^^^^^^^^^
  File "C:\Users\Spero 70\AppData\Local\Programs\Python\Python311\Lib\site-packages\django\utils\asyncio.py", line 26, in inner
    return func(*args, **kwargs)
           ^^^^^^^^^^^^^^^^^^^^^
  File "C:\Users\Spero 70\AppData\Local\Programs\Python\Python311\Lib\site-packages\django\db\backends\postgresql\base.py", line 332, in get_new_connection
    connection = self.Database.connect(**conn_params)
                 ^^^^^^^^^^^^^^^^^^^^^^^^^^^^^^^^^^^^
  File "C:\Users\Spero 70\AppData\Local\Programs\Python\Python311\Lib\site-packages\psycopg2\__init__.py", line 122, in connect
    conn = _connect(dsn, connection_factory=connection_factory, **kwasync)
           ^^^^^^^^^^^^^^^^^^^^^^^^^^^^^^^^^^^^^^^^^^^^^^^^^^^^^^^^^^^^^^^
django.db.utils.OperationalError: connection to server at "122.176.232.35", port 5433 failed: FATAL:  sorry, too many clients already
connection to server at "122.176.232.35", port 5433 failed: FATAL:  sorry, too many clients already

ERROR 2025-05-16 14:47:50,218 log Internal Server Error: /admin_web/Tahsil_get/
Traceback (most recent call last):
  File "C:\Users\Spero 70\AppData\Local\Programs\Python\Python311\Lib\site-packages\django\db\backends\base\base.py", line 279, in ensure_connection
    self.connect()
  File "C:\Users\Spero 70\AppData\Local\Programs\Python\Python311\Lib\site-packages\django\utils\asyncio.py", line 26, in inner
    return func(*args, **kwargs)
           ^^^^^^^^^^^^^^^^^^^^^
  File "C:\Users\Spero 70\AppData\Local\Programs\Python\Python311\Lib\site-packages\django\db\backends\base\base.py", line 256, in connect
    self.connection = self.get_new_connection(conn_params)
                      ^^^^^^^^^^^^^^^^^^^^^^^^^^^^^^^^^^^^
  File "C:\Users\Spero 70\AppData\Local\Programs\Python\Python311\Lib\site-packages\django\utils\asyncio.py", line 26, in inner
    return func(*args, **kwargs)
           ^^^^^^^^^^^^^^^^^^^^^
  File "C:\Users\Spero 70\AppData\Local\Programs\Python\Python311\Lib\site-packages\django\db\backends\postgresql\base.py", line 332, in get_new_connection
    connection = self.Database.connect(**conn_params)
                 ^^^^^^^^^^^^^^^^^^^^^^^^^^^^^^^^^^^^
  File "C:\Users\Spero 70\AppData\Local\Programs\Python\Python311\Lib\site-packages\psycopg2\__init__.py", line 122, in connect
    conn = _connect(dsn, connection_factory=connection_factory, **kwasync)
           ^^^^^^^^^^^^^^^^^^^^^^^^^^^^^^^^^^^^^^^^^^^^^^^^^^^^^^^^^^^^^^^
psycopg2.OperationalError: connection to server at "122.176.232.35", port 5433 failed: FATAL:  sorry, too many clients already
connection to server at "122.176.232.35", port 5433 failed: FATAL:  sorry, too many clients already


The above exception was the direct cause of the following exception:

Traceback (most recent call last):
  File "C:\Users\Spero 70\AppData\Local\Programs\Python\Python311\Lib\site-packages\django\core\handlers\exception.py", line 55, in inner
    response = get_response(request)
               ^^^^^^^^^^^^^^^^^^^^^
  File "C:\Users\Spero 70\AppData\Local\Programs\Python\Python311\Lib\site-packages\django\core\handlers\base.py", line 197, in _get_response
    response = wrapped_callback(request, *callback_args, **callback_kwargs)
               ^^^^^^^^^^^^^^^^^^^^^^^^^^^^^^^^^^^^^^^^^^^^^^^^^^^^^^^^^^^^
  File "C:\Users\Spero 70\AppData\Local\Programs\Python\Python311\Lib\site-packages\django\views\decorators\csrf.py", line 65, in _view_wrapper
    return view_func(request, *args, **kwargs)
           ^^^^^^^^^^^^^^^^^^^^^^^^^^^^^^^^^^^
  File "C:\Users\Spero 70\AppData\Local\Programs\Python\Python311\Lib\site-packages\django\views\generic\base.py", line 104, in view
    return self.dispatch(request, *args, **kwargs)
           ^^^^^^^^^^^^^^^^^^^^^^^^^^^^^^^^^^^^^^^
  File "C:\Users\Spero 70\AppData\Local\Programs\Python\Python311\Lib\site-packages\rest_framework\views.py", line 515, in dispatch
    response = self.handle_exception(exc)
               ^^^^^^^^^^^^^^^^^^^^^^^^^^
  File "C:\Users\Spero 70\AppData\Local\Programs\Python\Python311\Lib\site-packages\rest_framework\views.py", line 475, in handle_exception
    self.raise_uncaught_exception(exc)
  File "C:\Users\Spero 70\AppData\Local\Programs\Python\Python311\Lib\site-packages\rest_framework\views.py", line 486, in raise_uncaught_exception
    raise exc
  File "C:\Users\Spero 70\AppData\Local\Programs\Python\Python311\Lib\site-packages\rest_framework\views.py", line 503, in dispatch
    self.initial(request, *args, **kwargs)
  File "C:\Users\Spero 70\AppData\Local\Programs\Python\Python311\Lib\site-packages\rest_framework\views.py", line 420, in initial
    self.perform_authentication(request)
  File "C:\Users\Spero 70\AppData\Local\Programs\Python\Python311\Lib\site-packages\rest_framework\views.py", line 330, in perform_authentication
    request.user
  File "C:\Users\Spero 70\AppData\Local\Programs\Python\Python311\Lib\site-packages\rest_framework\request.py", line 232, in user
    self._authenticate()
  File "C:\Users\Spero 70\AppData\Local\Programs\Python\Python311\Lib\site-packages\rest_framework\request.py", line 385, in _authenticate
    user_auth_tuple = authenticator.authenticate(self)
                      ^^^^^^^^^^^^^^^^^^^^^^^^^^^^^^^^
  File "C:\Users\Spero 70\AppData\Local\Programs\Python\Python311\Lib\site-packages\rest_framework_simplejwt\authentication.py", line 51, in authenticate
    return self.get_user(validated_token), validated_token
           ^^^^^^^^^^^^^^^^^^^^^^^^^^^^^^
  File "C:\Users\Spero 70\AppData\Local\Programs\Python\Python311\Lib\site-packages\rest_framework_simplejwt\authentication.py", line 130, in get_user
    user = self.user_model.objects.get(**{api_settings.USER_ID_FIELD: user_id})
           ^^^^^^^^^^^^^^^^^^^^^^^^^^^^^^^^^^^^^^^^^^^^^^^^^^^^^^^^^^^^^^^^^^^^
  File "C:\Users\Spero 70\AppData\Local\Programs\Python\Python311\Lib\site-packages\django\db\models\manager.py", line 87, in manager_method
    return getattr(self.get_queryset(), name)(*args, **kwargs)
           ^^^^^^^^^^^^^^^^^^^^^^^^^^^^^^^^^^^^^^^^^^^^^^^^^^^
  File "C:\Users\Spero 70\AppData\Local\Programs\Python\Python311\Lib\site-packages\django\db\models\query.py", line 629, in get
    num = len(clone)
          ^^^^^^^^^^
  File "C:\Users\Spero 70\AppData\Local\Programs\Python\Python311\Lib\site-packages\django\db\models\query.py", line 366, in __len__
    self._fetch_all()
  File "C:\Users\Spero 70\AppData\Local\Programs\Python\Python311\Lib\site-packages\django\db\models\query.py", line 1935, in _fetch_all
    self._result_cache = list(self._iterable_class(self))
                         ^^^^^^^^^^^^^^^^^^^^^^^^^^^^^^^^
  File "C:\Users\Spero 70\AppData\Local\Programs\Python\Python311\Lib\site-packages\django\db\models\query.py", line 91, in __iter__
    results = compiler.execute_sql(
              ^^^^^^^^^^^^^^^^^^^^^
  File "C:\Users\Spero 70\AppData\Local\Programs\Python\Python311\Lib\site-packages\django\db\models\sql\compiler.py", line 1620, in execute_sql
    cursor = self.connection.cursor()
             ^^^^^^^^^^^^^^^^^^^^^^^^
  File "C:\Users\Spero 70\AppData\Local\Programs\Python\Python311\Lib\site-packages\django\utils\asyncio.py", line 26, in inner
    return func(*args, **kwargs)
           ^^^^^^^^^^^^^^^^^^^^^
  File "C:\Users\Spero 70\AppData\Local\Programs\Python\Python311\Lib\site-packages\django\db\backends\base\base.py", line 320, in cursor
    return self._cursor()
           ^^^^^^^^^^^^^^
  File "C:\Users\Spero 70\AppData\Local\Programs\Python\Python311\Lib\site-packages\django\db\backends\base\base.py", line 296, in _cursor
    self.ensure_connection()
  File "C:\Users\Spero 70\AppData\Local\Programs\Python\Python311\Lib\site-packages\django\utils\asyncio.py", line 26, in inner
    return func(*args, **kwargs)
           ^^^^^^^^^^^^^^^^^^^^^
  File "C:\Users\Spero 70\AppData\Local\Programs\Python\Python311\Lib\site-packages\django\db\backends\base\base.py", line 278, in ensure_connection
    with self.wrap_database_errors:
  File "C:\Users\Spero 70\AppData\Local\Programs\Python\Python311\Lib\site-packages\django\db\utils.py", line 91, in __exit__
    raise dj_exc_value.with_traceback(traceback) from exc_value
  File "C:\Users\Spero 70\AppData\Local\Programs\Python\Python311\Lib\site-packages\django\db\backends\base\base.py", line 279, in ensure_connection
    self.connect()
  File "C:\Users\Spero 70\AppData\Local\Programs\Python\Python311\Lib\site-packages\django\utils\asyncio.py", line 26, in inner
    return func(*args, **kwargs)
           ^^^^^^^^^^^^^^^^^^^^^
  File "C:\Users\Spero 70\AppData\Local\Programs\Python\Python311\Lib\site-packages\django\db\backends\base\base.py", line 256, in connect
    self.connection = self.get_new_connection(conn_params)
                      ^^^^^^^^^^^^^^^^^^^^^^^^^^^^^^^^^^^^
  File "C:\Users\Spero 70\AppData\Local\Programs\Python\Python311\Lib\site-packages\django\utils\asyncio.py", line 26, in inner
    return func(*args, **kwargs)
           ^^^^^^^^^^^^^^^^^^^^^
  File "C:\Users\Spero 70\AppData\Local\Programs\Python\Python311\Lib\site-packages\django\db\backends\postgresql\base.py", line 332, in get_new_connection
    connection = self.Database.connect(**conn_params)
                 ^^^^^^^^^^^^^^^^^^^^^^^^^^^^^^^^^^^^
  File "C:\Users\Spero 70\AppData\Local\Programs\Python\Python311\Lib\site-packages\psycopg2\__init__.py", line 122, in connect
    conn = _connect(dsn, connection_factory=connection_factory, **kwasync)
           ^^^^^^^^^^^^^^^^^^^^^^^^^^^^^^^^^^^^^^^^^^^^^^^^^^^^^^^^^^^^^^^
django.db.utils.OperationalError: connection to server at "122.176.232.35", port 5433 failed: FATAL:  sorry, too many clients already
connection to server at "122.176.232.35", port 5433 failed: FATAL:  sorry, too many clients already

ERROR 2025-05-16 14:47:50,235 basehttp "GET /admin_web/district_get/ HTTP/1.1" 500 228628
ERROR 2025-05-16 14:47:50,254 basehttp "GET /admin_web/Tahsil_get/ HTTP/1.1" 500 228568
ERROR 2025-05-16 14:47:50,444 log Internal Server Error: /admin_web/state_get/
Traceback (most recent call last):
  File "C:\Users\Spero 70\AppData\Local\Programs\Python\Python311\Lib\site-packages\django\db\backends\base\base.py", line 279, in ensure_connection
    self.connect()
  File "C:\Users\Spero 70\AppData\Local\Programs\Python\Python311\Lib\site-packages\django\utils\asyncio.py", line 26, in inner
    return func(*args, **kwargs)
           ^^^^^^^^^^^^^^^^^^^^^
  File "C:\Users\Spero 70\AppData\Local\Programs\Python\Python311\Lib\site-packages\django\db\backends\base\base.py", line 256, in connect
    self.connection = self.get_new_connection(conn_params)
                      ^^^^^^^^^^^^^^^^^^^^^^^^^^^^^^^^^^^^
  File "C:\Users\Spero 70\AppData\Local\Programs\Python\Python311\Lib\site-packages\django\utils\asyncio.py", line 26, in inner
    return func(*args, **kwargs)
           ^^^^^^^^^^^^^^^^^^^^^
  File "C:\Users\Spero 70\AppData\Local\Programs\Python\Python311\Lib\site-packages\django\db\backends\postgresql\base.py", line 332, in get_new_connection
    connection = self.Database.connect(**conn_params)
                 ^^^^^^^^^^^^^^^^^^^^^^^^^^^^^^^^^^^^
  File "C:\Users\Spero 70\AppData\Local\Programs\Python\Python311\Lib\site-packages\psycopg2\__init__.py", line 122, in connect
    conn = _connect(dsn, connection_factory=connection_factory, **kwasync)
           ^^^^^^^^^^^^^^^^^^^^^^^^^^^^^^^^^^^^^^^^^^^^^^^^^^^^^^^^^^^^^^^
psycopg2.OperationalError: connection to server at "122.176.232.35", port 5433 failed: FATAL:  sorry, too many clients already
connection to server at "122.176.232.35", port 5433 failed: FATAL:  sorry, too many clients already


The above exception was the direct cause of the following exception:

Traceback (most recent call last):
  File "C:\Users\Spero 70\AppData\Local\Programs\Python\Python311\Lib\site-packages\django\core\handlers\exception.py", line 55, in inner
    response = get_response(request)
               ^^^^^^^^^^^^^^^^^^^^^
  File "C:\Users\Spero 70\AppData\Local\Programs\Python\Python311\Lib\site-packages\django\core\handlers\base.py", line 197, in _get_response
    response = wrapped_callback(request, *callback_args, **callback_kwargs)
               ^^^^^^^^^^^^^^^^^^^^^^^^^^^^^^^^^^^^^^^^^^^^^^^^^^^^^^^^^^^^
  File "C:\Users\Spero 70\AppData\Local\Programs\Python\Python311\Lib\site-packages\django\views\decorators\csrf.py", line 65, in _view_wrapper
    return view_func(request, *args, **kwargs)
           ^^^^^^^^^^^^^^^^^^^^^^^^^^^^^^^^^^^
  File "C:\Users\Spero 70\AppData\Local\Programs\Python\Python311\Lib\site-packages\django\views\generic\base.py", line 104, in view
    return self.dispatch(request, *args, **kwargs)
           ^^^^^^^^^^^^^^^^^^^^^^^^^^^^^^^^^^^^^^^
  File "C:\Users\Spero 70\AppData\Local\Programs\Python\Python311\Lib\site-packages\rest_framework\views.py", line 515, in dispatch
    response = self.handle_exception(exc)
               ^^^^^^^^^^^^^^^^^^^^^^^^^^
  File "C:\Users\Spero 70\AppData\Local\Programs\Python\Python311\Lib\site-packages\rest_framework\views.py", line 475, in handle_exception
    self.raise_uncaught_exception(exc)
  File "C:\Users\Spero 70\AppData\Local\Programs\Python\Python311\Lib\site-packages\rest_framework\views.py", line 486, in raise_uncaught_exception
    raise exc
  File "C:\Users\Spero 70\AppData\Local\Programs\Python\Python311\Lib\site-packages\rest_framework\views.py", line 512, in dispatch
    response = handler(request, *args, **kwargs)
               ^^^^^^^^^^^^^^^^^^^^^^^^^^^^^^^^^
  File "D:\Spero-DMS\DMS_goa\admin_web\views.py", line 168, in get
    return Response(serializers.data,status=status.HTTP_200_OK)
                    ^^^^^^^^^^^^^^^^
  File "C:\Users\Spero 70\AppData\Local\Programs\Python\Python311\Lib\site-packages\rest_framework\serializers.py", line 797, in data
    ret = super().data
          ^^^^^^^^^^^^
  File "C:\Users\Spero 70\AppData\Local\Programs\Python\Python311\Lib\site-packages\rest_framework\serializers.py", line 251, in data
    self._data = self.to_representation(self.instance)
                 ^^^^^^^^^^^^^^^^^^^^^^^^^^^^^^^^^^^^^
  File "C:\Users\Spero 70\AppData\Local\Programs\Python\Python311\Lib\site-packages\rest_framework\serializers.py", line 715, in to_representation
    return [
           ^
  File "C:\Users\Spero 70\AppData\Local\Programs\Python\Python311\Lib\site-packages\django\db\models\query.py", line 384, in __iter__
    self._fetch_all()
  File "C:\Users\Spero 70\AppData\Local\Programs\Python\Python311\Lib\site-packages\django\db\models\query.py", line 1935, in _fetch_all
    self._result_cache = list(self._iterable_class(self))
                         ^^^^^^^^^^^^^^^^^^^^^^^^^^^^^^^^
  File "C:\Users\Spero 70\AppData\Local\Programs\Python\Python311\Lib\site-packages\django\db\models\query.py", line 91, in __iter__
    results = compiler.execute_sql(
              ^^^^^^^^^^^^^^^^^^^^^
  File "C:\Users\Spero 70\AppData\Local\Programs\Python\Python311\Lib\site-packages\django\db\models\sql\compiler.py", line 1620, in execute_sql
    cursor = self.connection.cursor()
             ^^^^^^^^^^^^^^^^^^^^^^^^
  File "C:\Users\Spero 70\AppData\Local\Programs\Python\Python311\Lib\site-packages\django\utils\asyncio.py", line 26, in inner
    return func(*args, **kwargs)
           ^^^^^^^^^^^^^^^^^^^^^
  File "C:\Users\Spero 70\AppData\Local\Programs\Python\Python311\Lib\site-packages\django\db\backends\base\base.py", line 320, in cursor
    return self._cursor()
           ^^^^^^^^^^^^^^
  File "C:\Users\Spero 70\AppData\Local\Programs\Python\Python311\Lib\site-packages\django\db\backends\base\base.py", line 296, in _cursor
    self.ensure_connection()
  File "C:\Users\Spero 70\AppData\Local\Programs\Python\Python311\Lib\site-packages\django\utils\asyncio.py", line 26, in inner
    return func(*args, **kwargs)
           ^^^^^^^^^^^^^^^^^^^^^
  File "C:\Users\Spero 70\AppData\Local\Programs\Python\Python311\Lib\site-packages\django\db\backends\base\base.py", line 278, in ensure_connection
    with self.wrap_database_errors:
  File "C:\Users\Spero 70\AppData\Local\Programs\Python\Python311\Lib\site-packages\django\db\utils.py", line 91, in __exit__
    raise dj_exc_value.with_traceback(traceback) from exc_value
  File "C:\Users\Spero 70\AppData\Local\Programs\Python\Python311\Lib\site-packages\django\db\backends\base\base.py", line 279, in ensure_connection
    self.connect()
  File "C:\Users\Spero 70\AppData\Local\Programs\Python\Python311\Lib\site-packages\django\utils\asyncio.py", line 26, in inner
    return func(*args, **kwargs)
           ^^^^^^^^^^^^^^^^^^^^^
  File "C:\Users\Spero 70\AppData\Local\Programs\Python\Python311\Lib\site-packages\django\db\backends\base\base.py", line 256, in connect
    self.connection = self.get_new_connection(conn_params)
                      ^^^^^^^^^^^^^^^^^^^^^^^^^^^^^^^^^^^^
  File "C:\Users\Spero 70\AppData\Local\Programs\Python\Python311\Lib\site-packages\django\utils\asyncio.py", line 26, in inner
    return func(*args, **kwargs)
           ^^^^^^^^^^^^^^^^^^^^^
  File "C:\Users\Spero 70\AppData\Local\Programs\Python\Python311\Lib\site-packages\django\db\backends\postgresql\base.py", line 332, in get_new_connection
    connection = self.Database.connect(**conn_params)
                 ^^^^^^^^^^^^^^^^^^^^^^^^^^^^^^^^^^^^
  File "C:\Users\Spero 70\AppData\Local\Programs\Python\Python311\Lib\site-packages\psycopg2\__init__.py", line 122, in connect
    conn = _connect(dsn, connection_factory=connection_factory, **kwasync)
           ^^^^^^^^^^^^^^^^^^^^^^^^^^^^^^^^^^^^^^^^^^^^^^^^^^^^^^^^^^^^^^^
django.db.utils.OperationalError: connection to server at "122.176.232.35", port 5433 failed: FATAL:  sorry, too many clients already
connection to server at "122.176.232.35", port 5433 failed: FATAL:  sorry, too many clients already

ERROR 2025-05-16 14:47:50,471 basehttp "GET /admin_web/state_get/ HTTP/1.1" 500 210109
ERROR 2025-05-16 14:47:50,884 log Internal Server Error: /admin_web/district_get/
Traceback (most recent call last):
  File "C:\Users\Spero 70\AppData\Local\Programs\Python\Python311\Lib\site-packages\django\db\backends\base\base.py", line 279, in ensure_connection
    self.connect()
  File "C:\Users\Spero 70\AppData\Local\Programs\Python\Python311\Lib\site-packages\django\utils\asyncio.py", line 26, in inner
    return func(*args, **kwargs)
           ^^^^^^^^^^^^^^^^^^^^^
  File "C:\Users\Spero 70\AppData\Local\Programs\Python\Python311\Lib\site-packages\django\db\backends\base\base.py", line 256, in connect
    self.connection = self.get_new_connection(conn_params)
                      ^^^^^^^^^^^^^^^^^^^^^^^^^^^^^^^^^^^^
  File "C:\Users\Spero 70\AppData\Local\Programs\Python\Python311\Lib\site-packages\django\utils\asyncio.py", line 26, in inner
    return func(*args, **kwargs)
           ^^^^^^^^^^^^^^^^^^^^^
  File "C:\Users\Spero 70\AppData\Local\Programs\Python\Python311\Lib\site-packages\django\db\backends\postgresql\base.py", line 332, in get_new_connection
    connection = self.Database.connect(**conn_params)
                 ^^^^^^^^^^^^^^^^^^^^^^^^^^^^^^^^^^^^
  File "C:\Users\Spero 70\AppData\Local\Programs\Python\Python311\Lib\site-packages\psycopg2\__init__.py", line 122, in connect
    conn = _connect(dsn, connection_factory=connection_factory, **kwasync)
           ^^^^^^^^^^^^^^^^^^^^^^^^^^^^^^^^^^^^^^^^^^^^^^^^^^^^^^^^^^^^^^^
psycopg2.OperationalError: connection to server at "122.176.232.35", port 5433 failed: FATAL:  sorry, too many clients already
connection to server at "122.176.232.35", port 5433 failed: FATAL:  sorry, too many clients already


The above exception was the direct cause of the following exception:

Traceback (most recent call last):
  File "C:\Users\Spero 70\AppData\Local\Programs\Python\Python311\Lib\site-packages\django\core\handlers\exception.py", line 55, in inner
    response = get_response(request)
               ^^^^^^^^^^^^^^^^^^^^^
  File "C:\Users\Spero 70\AppData\Local\Programs\Python\Python311\Lib\site-packages\django\core\handlers\base.py", line 197, in _get_response
    response = wrapped_callback(request, *callback_args, **callback_kwargs)
               ^^^^^^^^^^^^^^^^^^^^^^^^^^^^^^^^^^^^^^^^^^^^^^^^^^^^^^^^^^^^
  File "C:\Users\Spero 70\AppData\Local\Programs\Python\Python311\Lib\site-packages\django\views\decorators\csrf.py", line 65, in _view_wrapper
    return view_func(request, *args, **kwargs)
           ^^^^^^^^^^^^^^^^^^^^^^^^^^^^^^^^^^^
  File "C:\Users\Spero 70\AppData\Local\Programs\Python\Python311\Lib\site-packages\django\views\generic\base.py", line 104, in view
    return self.dispatch(request, *args, **kwargs)
           ^^^^^^^^^^^^^^^^^^^^^^^^^^^^^^^^^^^^^^^
  File "C:\Users\Spero 70\AppData\Local\Programs\Python\Python311\Lib\site-packages\rest_framework\views.py", line 515, in dispatch
    response = self.handle_exception(exc)
               ^^^^^^^^^^^^^^^^^^^^^^^^^^
  File "C:\Users\Spero 70\AppData\Local\Programs\Python\Python311\Lib\site-packages\rest_framework\views.py", line 475, in handle_exception
    self.raise_uncaught_exception(exc)
  File "C:\Users\Spero 70\AppData\Local\Programs\Python\Python311\Lib\site-packages\rest_framework\views.py", line 486, in raise_uncaught_exception
    raise exc
  File "C:\Users\Spero 70\AppData\Local\Programs\Python\Python311\Lib\site-packages\rest_framework\views.py", line 503, in dispatch
    self.initial(request, *args, **kwargs)
  File "C:\Users\Spero 70\AppData\Local\Programs\Python\Python311\Lib\site-packages\rest_framework\views.py", line 420, in initial
    self.perform_authentication(request)
  File "C:\Users\Spero 70\AppData\Local\Programs\Python\Python311\Lib\site-packages\rest_framework\views.py", line 330, in perform_authentication
    request.user
  File "C:\Users\Spero 70\AppData\Local\Programs\Python\Python311\Lib\site-packages\rest_framework\request.py", line 232, in user
    self._authenticate()
  File "C:\Users\Spero 70\AppData\Local\Programs\Python\Python311\Lib\site-packages\rest_framework\request.py", line 385, in _authenticate
    user_auth_tuple = authenticator.authenticate(self)
                      ^^^^^^^^^^^^^^^^^^^^^^^^^^^^^^^^
  File "C:\Users\Spero 70\AppData\Local\Programs\Python\Python311\Lib\site-packages\rest_framework_simplejwt\authentication.py", line 51, in authenticate
    return self.get_user(validated_token), validated_token
           ^^^^^^^^^^^^^^^^^^^^^^^^^^^^^^
  File "C:\Users\Spero 70\AppData\Local\Programs\Python\Python311\Lib\site-packages\rest_framework_simplejwt\authentication.py", line 130, in get_user
    user = self.user_model.objects.get(**{api_settings.USER_ID_FIELD: user_id})
           ^^^^^^^^^^^^^^^^^^^^^^^^^^^^^^^^^^^^^^^^^^^^^^^^^^^^^^^^^^^^^^^^^^^^
  File "C:\Users\Spero 70\AppData\Local\Programs\Python\Python311\Lib\site-packages\django\db\models\manager.py", line 87, in manager_method
    return getattr(self.get_queryset(), name)(*args, **kwargs)
           ^^^^^^^^^^^^^^^^^^^^^^^^^^^^^^^^^^^^^^^^^^^^^^^^^^^
  File "C:\Users\Spero 70\AppData\Local\Programs\Python\Python311\Lib\site-packages\django\db\models\query.py", line 629, in get
    num = len(clone)
          ^^^^^^^^^^
  File "C:\Users\Spero 70\AppData\Local\Programs\Python\Python311\Lib\site-packages\django\db\models\query.py", line 366, in __len__
    self._fetch_all()
  File "C:\Users\Spero 70\AppData\Local\Programs\Python\Python311\Lib\site-packages\django\db\models\query.py", line 1935, in _fetch_all
    self._result_cache = list(self._iterable_class(self))
                         ^^^^^^^^^^^^^^^^^^^^^^^^^^^^^^^^
  File "C:\Users\Spero 70\AppData\Local\Programs\Python\Python311\Lib\site-packages\django\db\models\query.py", line 91, in __iter__
    results = compiler.execute_sql(
              ^^^^^^^^^^^^^^^^^^^^^
  File "C:\Users\Spero 70\AppData\Local\Programs\Python\Python311\Lib\site-packages\django\db\models\sql\compiler.py", line 1620, in execute_sql
    cursor = self.connection.cursor()
             ^^^^^^^^^^^^^^^^^^^^^^^^
  File "C:\Users\Spero 70\AppData\Local\Programs\Python\Python311\Lib\site-packages\django\utils\asyncio.py", line 26, in inner
    return func(*args, **kwargs)
           ^^^^^^^^^^^^^^^^^^^^^
  File "C:\Users\Spero 70\AppData\Local\Programs\Python\Python311\Lib\site-packages\django\db\backends\base\base.py", line 320, in cursor
    return self._cursor()
           ^^^^^^^^^^^^^^
  File "C:\Users\Spero 70\AppData\Local\Programs\Python\Python311\Lib\site-packages\django\db\backends\base\base.py", line 296, in _cursor
    self.ensure_connection()
  File "C:\Users\Spero 70\AppData\Local\Programs\Python\Python311\Lib\site-packages\django\utils\asyncio.py", line 26, in inner
    return func(*args, **kwargs)
           ^^^^^^^^^^^^^^^^^^^^^
  File "C:\Users\Spero 70\AppData\Local\Programs\Python\Python311\Lib\site-packages\django\db\backends\base\base.py", line 278, in ensure_connection
    with self.wrap_database_errors:
  File "C:\Users\Spero 70\AppData\Local\Programs\Python\Python311\Lib\site-packages\django\db\utils.py", line 91, in __exit__
    raise dj_exc_value.with_traceback(traceback) from exc_value
  File "C:\Users\Spero 70\AppData\Local\Programs\Python\Python311\Lib\site-packages\django\db\backends\base\base.py", line 279, in ensure_connection
    self.connect()
  File "C:\Users\Spero 70\AppData\Local\Programs\Python\Python311\Lib\site-packages\django\utils\asyncio.py", line 26, in inner
    return func(*args, **kwargs)
           ^^^^^^^^^^^^^^^^^^^^^
  File "C:\Users\Spero 70\AppData\Local\Programs\Python\Python311\Lib\site-packages\django\db\backends\base\base.py", line 256, in connect
    self.connection = self.get_new_connection(conn_params)
                      ^^^^^^^^^^^^^^^^^^^^^^^^^^^^^^^^^^^^
  File "C:\Users\Spero 70\AppData\Local\Programs\Python\Python311\Lib\site-packages\django\utils\asyncio.py", line 26, in inner
    return func(*args, **kwargs)
           ^^^^^^^^^^^^^^^^^^^^^
  File "C:\Users\Spero 70\AppData\Local\Programs\Python\Python311\Lib\site-packages\django\db\backends\postgresql\base.py", line 332, in get_new_connection
    connection = self.Database.connect(**conn_params)
                 ^^^^^^^^^^^^^^^^^^^^^^^^^^^^^^^^^^^^
  File "C:\Users\Spero 70\AppData\Local\Programs\Python\Python311\Lib\site-packages\psycopg2\__init__.py", line 122, in connect
    conn = _connect(dsn, connection_factory=connection_factory, **kwasync)
           ^^^^^^^^^^^^^^^^^^^^^^^^^^^^^^^^^^^^^^^^^^^^^^^^^^^^^^^^^^^^^^^
django.db.utils.OperationalError: connection to server at "122.176.232.35", port 5433 failed: FATAL:  sorry, too many clients already
connection to server at "122.176.232.35", port 5433 failed: FATAL:  sorry, too many clients already

ERROR 2025-05-16 14:47:50,979 log Internal Server Error: /admin_web/Tahsil_get/
Traceback (most recent call last):
  File "C:\Users\Spero 70\AppData\Local\Programs\Python\Python311\Lib\site-packages\django\db\backends\base\base.py", line 279, in ensure_connection
    self.connect()
  File "C:\Users\Spero 70\AppData\Local\Programs\Python\Python311\Lib\site-packages\django\utils\asyncio.py", line 26, in inner
    return func(*args, **kwargs)
           ^^^^^^^^^^^^^^^^^^^^^
  File "C:\Users\Spero 70\AppData\Local\Programs\Python\Python311\Lib\site-packages\django\db\backends\base\base.py", line 256, in connect
    self.connection = self.get_new_connection(conn_params)
                      ^^^^^^^^^^^^^^^^^^^^^^^^^^^^^^^^^^^^
  File "C:\Users\Spero 70\AppData\Local\Programs\Python\Python311\Lib\site-packages\django\utils\asyncio.py", line 26, in inner
    return func(*args, **kwargs)
           ^^^^^^^^^^^^^^^^^^^^^
  File "C:\Users\Spero 70\AppData\Local\Programs\Python\Python311\Lib\site-packages\django\db\backends\postgresql\base.py", line 332, in get_new_connection
    connection = self.Database.connect(**conn_params)
                 ^^^^^^^^^^^^^^^^^^^^^^^^^^^^^^^^^^^^
  File "C:\Users\Spero 70\AppData\Local\Programs\Python\Python311\Lib\site-packages\psycopg2\__init__.py", line 122, in connect
    conn = _connect(dsn, connection_factory=connection_factory, **kwasync)
           ^^^^^^^^^^^^^^^^^^^^^^^^^^^^^^^^^^^^^^^^^^^^^^^^^^^^^^^^^^^^^^^
psycopg2.OperationalError: connection to server at "122.176.232.35", port 5433 failed: FATAL:  sorry, too many clients already
connection to server at "122.176.232.35", port 5433 failed: FATAL:  sorry, too many clients already


The above exception was the direct cause of the following exception:

Traceback (most recent call last):
  File "C:\Users\Spero 70\AppData\Local\Programs\Python\Python311\Lib\site-packages\django\core\handlers\exception.py", line 55, in inner
    response = get_response(request)
               ^^^^^^^^^^^^^^^^^^^^^
  File "C:\Users\Spero 70\AppData\Local\Programs\Python\Python311\Lib\site-packages\django\core\handlers\base.py", line 197, in _get_response
    response = wrapped_callback(request, *callback_args, **callback_kwargs)
               ^^^^^^^^^^^^^^^^^^^^^^^^^^^^^^^^^^^^^^^^^^^^^^^^^^^^^^^^^^^^
  File "C:\Users\Spero 70\AppData\Local\Programs\Python\Python311\Lib\site-packages\django\views\decorators\csrf.py", line 65, in _view_wrapper
    return view_func(request, *args, **kwargs)
           ^^^^^^^^^^^^^^^^^^^^^^^^^^^^^^^^^^^
  File "C:\Users\Spero 70\AppData\Local\Programs\Python\Python311\Lib\site-packages\django\views\generic\base.py", line 104, in view
    return self.dispatch(request, *args, **kwargs)
           ^^^^^^^^^^^^^^^^^^^^^^^^^^^^^^^^^^^^^^^
  File "C:\Users\Spero 70\AppData\Local\Programs\Python\Python311\Lib\site-packages\rest_framework\views.py", line 515, in dispatch
    response = self.handle_exception(exc)
               ^^^^^^^^^^^^^^^^^^^^^^^^^^
  File "C:\Users\Spero 70\AppData\Local\Programs\Python\Python311\Lib\site-packages\rest_framework\views.py", line 475, in handle_exception
    self.raise_uncaught_exception(exc)
  File "C:\Users\Spero 70\AppData\Local\Programs\Python\Python311\Lib\site-packages\rest_framework\views.py", line 486, in raise_uncaught_exception
    raise exc
  File "C:\Users\Spero 70\AppData\Local\Programs\Python\Python311\Lib\site-packages\rest_framework\views.py", line 503, in dispatch
    self.initial(request, *args, **kwargs)
  File "C:\Users\Spero 70\AppData\Local\Programs\Python\Python311\Lib\site-packages\rest_framework\views.py", line 420, in initial
    self.perform_authentication(request)
  File "C:\Users\Spero 70\AppData\Local\Programs\Python\Python311\Lib\site-packages\rest_framework\views.py", line 330, in perform_authentication
    request.user
  File "C:\Users\Spero 70\AppData\Local\Programs\Python\Python311\Lib\site-packages\rest_framework\request.py", line 232, in user
    self._authenticate()
  File "C:\Users\Spero 70\AppData\Local\Programs\Python\Python311\Lib\site-packages\rest_framework\request.py", line 385, in _authenticate
    user_auth_tuple = authenticator.authenticate(self)
                      ^^^^^^^^^^^^^^^^^^^^^^^^^^^^^^^^
  File "C:\Users\Spero 70\AppData\Local\Programs\Python\Python311\Lib\site-packages\rest_framework_simplejwt\authentication.py", line 51, in authenticate
    return self.get_user(validated_token), validated_token
           ^^^^^^^^^^^^^^^^^^^^^^^^^^^^^^
  File "C:\Users\Spero 70\AppData\Local\Programs\Python\Python311\Lib\site-packages\rest_framework_simplejwt\authentication.py", line 130, in get_user
    user = self.user_model.objects.get(**{api_settings.USER_ID_FIELD: user_id})
           ^^^^^^^^^^^^^^^^^^^^^^^^^^^^^^^^^^^^^^^^^^^^^^^^^^^^^^^^^^^^^^^^^^^^
  File "C:\Users\Spero 70\AppData\Local\Programs\Python\Python311\Lib\site-packages\django\db\models\manager.py", line 87, in manager_method
    return getattr(self.get_queryset(), name)(*args, **kwargs)
           ^^^^^^^^^^^^^^^^^^^^^^^^^^^^^^^^^^^^^^^^^^^^^^^^^^^
  File "C:\Users\Spero 70\AppData\Local\Programs\Python\Python311\Lib\site-packages\django\db\models\query.py", line 629, in get
    num = len(clone)
          ^^^^^^^^^^
  File "C:\Users\Spero 70\AppData\Local\Programs\Python\Python311\Lib\site-packages\django\db\models\query.py", line 366, in __len__
    self._fetch_all()
  File "C:\Users\Spero 70\AppData\Local\Programs\Python\Python311\Lib\site-packages\django\db\models\query.py", line 1935, in _fetch_all
    self._result_cache = list(self._iterable_class(self))
                         ^^^^^^^^^^^^^^^^^^^^^^^^^^^^^^^^
  File "C:\Users\Spero 70\AppData\Local\Programs\Python\Python311\Lib\site-packages\django\db\models\query.py", line 91, in __iter__
    results = compiler.execute_sql(
              ^^^^^^^^^^^^^^^^^^^^^
  File "C:\Users\Spero 70\AppData\Local\Programs\Python\Python311\Lib\site-packages\django\db\models\sql\compiler.py", line 1620, in execute_sql
    cursor = self.connection.cursor()
             ^^^^^^^^^^^^^^^^^^^^^^^^
  File "C:\Users\Spero 70\AppData\Local\Programs\Python\Python311\Lib\site-packages\django\utils\asyncio.py", line 26, in inner
    return func(*args, **kwargs)
           ^^^^^^^^^^^^^^^^^^^^^
  File "C:\Users\Spero 70\AppData\Local\Programs\Python\Python311\Lib\site-packages\django\db\backends\base\base.py", line 320, in cursor
    return self._cursor()
           ^^^^^^^^^^^^^^
  File "C:\Users\Spero 70\AppData\Local\Programs\Python\Python311\Lib\site-packages\django\db\backends\base\base.py", line 296, in _cursor
    self.ensure_connection()
  File "C:\Users\Spero 70\AppData\Local\Programs\Python\Python311\Lib\site-packages\django\utils\asyncio.py", line 26, in inner
    return func(*args, **kwargs)
           ^^^^^^^^^^^^^^^^^^^^^
  File "C:\Users\Spero 70\AppData\Local\Programs\Python\Python311\Lib\site-packages\django\db\backends\base\base.py", line 278, in ensure_connection
    with self.wrap_database_errors:
  File "C:\Users\Spero 70\AppData\Local\Programs\Python\Python311\Lib\site-packages\django\db\utils.py", line 91, in __exit__
    raise dj_exc_value.with_traceback(traceback) from exc_value
  File "C:\Users\Spero 70\AppData\Local\Programs\Python\Python311\Lib\site-packages\django\db\backends\base\base.py", line 279, in ensure_connection
    self.connect()
  File "C:\Users\Spero 70\AppData\Local\Programs\Python\Python311\Lib\site-packages\django\utils\asyncio.py", line 26, in inner
    return func(*args, **kwargs)
           ^^^^^^^^^^^^^^^^^^^^^
  File "C:\Users\Spero 70\AppData\Local\Programs\Python\Python311\Lib\site-packages\django\db\backends\base\base.py", line 256, in connect
    self.connection = self.get_new_connection(conn_params)
                      ^^^^^^^^^^^^^^^^^^^^^^^^^^^^^^^^^^^^
  File "C:\Users\Spero 70\AppData\Local\Programs\Python\Python311\Lib\site-packages\django\utils\asyncio.py", line 26, in inner
    return func(*args, **kwargs)
           ^^^^^^^^^^^^^^^^^^^^^
  File "C:\Users\Spero 70\AppData\Local\Programs\Python\Python311\Lib\site-packages\django\db\backends\postgresql\base.py", line 332, in get_new_connection
    connection = self.Database.connect(**conn_params)
                 ^^^^^^^^^^^^^^^^^^^^^^^^^^^^^^^^^^^^
  File "C:\Users\Spero 70\AppData\Local\Programs\Python\Python311\Lib\site-packages\psycopg2\__init__.py", line 122, in connect
    conn = _connect(dsn, connection_factory=connection_factory, **kwasync)
           ^^^^^^^^^^^^^^^^^^^^^^^^^^^^^^^^^^^^^^^^^^^^^^^^^^^^^^^^^^^^^^^
django.db.utils.OperationalError: connection to server at "122.176.232.35", port 5433 failed: FATAL:  sorry, too many clients already
connection to server at "122.176.232.35", port 5433 failed: FATAL:  sorry, too many clients already

ERROR 2025-05-16 14:47:51,002 basehttp "GET /admin_web/district_get/ HTTP/1.1" 500 228628
ERROR 2025-05-16 14:47:51,026 basehttp "GET /admin_web/Tahsil_get/ HTTP/1.1" 500 228568
ERROR 2025-05-16 14:47:51,393 log Internal Server Error: /admin_web/state_get/
Traceback (most recent call last):
  File "C:\Users\Spero 70\AppData\Local\Programs\Python\Python311\Lib\site-packages\django\db\backends\base\base.py", line 279, in ensure_connection
    self.connect()
  File "C:\Users\Spero 70\AppData\Local\Programs\Python\Python311\Lib\site-packages\django\utils\asyncio.py", line 26, in inner
    return func(*args, **kwargs)
           ^^^^^^^^^^^^^^^^^^^^^
  File "C:\Users\Spero 70\AppData\Local\Programs\Python\Python311\Lib\site-packages\django\db\backends\base\base.py", line 256, in connect
    self.connection = self.get_new_connection(conn_params)
                      ^^^^^^^^^^^^^^^^^^^^^^^^^^^^^^^^^^^^
  File "C:\Users\Spero 70\AppData\Local\Programs\Python\Python311\Lib\site-packages\django\utils\asyncio.py", line 26, in inner
    return func(*args, **kwargs)
           ^^^^^^^^^^^^^^^^^^^^^
  File "C:\Users\Spero 70\AppData\Local\Programs\Python\Python311\Lib\site-packages\django\db\backends\postgresql\base.py", line 332, in get_new_connection
    connection = self.Database.connect(**conn_params)
                 ^^^^^^^^^^^^^^^^^^^^^^^^^^^^^^^^^^^^
  File "C:\Users\Spero 70\AppData\Local\Programs\Python\Python311\Lib\site-packages\psycopg2\__init__.py", line 122, in connect
    conn = _connect(dsn, connection_factory=connection_factory, **kwasync)
           ^^^^^^^^^^^^^^^^^^^^^^^^^^^^^^^^^^^^^^^^^^^^^^^^^^^^^^^^^^^^^^^
psycopg2.OperationalError: connection to server at "122.176.232.35", port 5433 failed: FATAL:  sorry, too many clients already
connection to server at "122.176.232.35", port 5433 failed: FATAL:  sorry, too many clients already


The above exception was the direct cause of the following exception:

Traceback (most recent call last):
  File "C:\Users\Spero 70\AppData\Local\Programs\Python\Python311\Lib\site-packages\django\core\handlers\exception.py", line 55, in inner
    response = get_response(request)
               ^^^^^^^^^^^^^^^^^^^^^
  File "C:\Users\Spero 70\AppData\Local\Programs\Python\Python311\Lib\site-packages\django\core\handlers\base.py", line 197, in _get_response
    response = wrapped_callback(request, *callback_args, **callback_kwargs)
               ^^^^^^^^^^^^^^^^^^^^^^^^^^^^^^^^^^^^^^^^^^^^^^^^^^^^^^^^^^^^
  File "C:\Users\Spero 70\AppData\Local\Programs\Python\Python311\Lib\site-packages\django\views\decorators\csrf.py", line 65, in _view_wrapper
    return view_func(request, *args, **kwargs)
           ^^^^^^^^^^^^^^^^^^^^^^^^^^^^^^^^^^^
  File "C:\Users\Spero 70\AppData\Local\Programs\Python\Python311\Lib\site-packages\django\views\generic\base.py", line 104, in view
    return self.dispatch(request, *args, **kwargs)
           ^^^^^^^^^^^^^^^^^^^^^^^^^^^^^^^^^^^^^^^
  File "C:\Users\Spero 70\AppData\Local\Programs\Python\Python311\Lib\site-packages\rest_framework\views.py", line 515, in dispatch
    response = self.handle_exception(exc)
               ^^^^^^^^^^^^^^^^^^^^^^^^^^
  File "C:\Users\Spero 70\AppData\Local\Programs\Python\Python311\Lib\site-packages\rest_framework\views.py", line 475, in handle_exception
    self.raise_uncaught_exception(exc)
  File "C:\Users\Spero 70\AppData\Local\Programs\Python\Python311\Lib\site-packages\rest_framework\views.py", line 486, in raise_uncaught_exception
    raise exc
  File "C:\Users\Spero 70\AppData\Local\Programs\Python\Python311\Lib\site-packages\rest_framework\views.py", line 512, in dispatch
    response = handler(request, *args, **kwargs)
               ^^^^^^^^^^^^^^^^^^^^^^^^^^^^^^^^^
  File "D:\Spero-DMS\DMS_goa\admin_web\views.py", line 168, in get
    return Response(serializers.data,status=status.HTTP_200_OK)
                    ^^^^^^^^^^^^^^^^
  File "C:\Users\Spero 70\AppData\Local\Programs\Python\Python311\Lib\site-packages\rest_framework\serializers.py", line 797, in data
    ret = super().data
          ^^^^^^^^^^^^
  File "C:\Users\Spero 70\AppData\Local\Programs\Python\Python311\Lib\site-packages\rest_framework\serializers.py", line 251, in data
    self._data = self.to_representation(self.instance)
                 ^^^^^^^^^^^^^^^^^^^^^^^^^^^^^^^^^^^^^
  File "C:\Users\Spero 70\AppData\Local\Programs\Python\Python311\Lib\site-packages\rest_framework\serializers.py", line 715, in to_representation
    return [
           ^
  File "C:\Users\Spero 70\AppData\Local\Programs\Python\Python311\Lib\site-packages\django\db\models\query.py", line 384, in __iter__
    self._fetch_all()
  File "C:\Users\Spero 70\AppData\Local\Programs\Python\Python311\Lib\site-packages\django\db\models\query.py", line 1935, in _fetch_all
    self._result_cache = list(self._iterable_class(self))
                         ^^^^^^^^^^^^^^^^^^^^^^^^^^^^^^^^
  File "C:\Users\Spero 70\AppData\Local\Programs\Python\Python311\Lib\site-packages\django\db\models\query.py", line 91, in __iter__
    results = compiler.execute_sql(
              ^^^^^^^^^^^^^^^^^^^^^
  File "C:\Users\Spero 70\AppData\Local\Programs\Python\Python311\Lib\site-packages\django\db\models\sql\compiler.py", line 1620, in execute_sql
    cursor = self.connection.cursor()
             ^^^^^^^^^^^^^^^^^^^^^^^^
  File "C:\Users\Spero 70\AppData\Local\Programs\Python\Python311\Lib\site-packages\django\utils\asyncio.py", line 26, in inner
    return func(*args, **kwargs)
           ^^^^^^^^^^^^^^^^^^^^^
  File "C:\Users\Spero 70\AppData\Local\Programs\Python\Python311\Lib\site-packages\django\db\backends\base\base.py", line 320, in cursor
    return self._cursor()
           ^^^^^^^^^^^^^^
  File "C:\Users\Spero 70\AppData\Local\Programs\Python\Python311\Lib\site-packages\django\db\backends\base\base.py", line 296, in _cursor
    self.ensure_connection()
  File "C:\Users\Spero 70\AppData\Local\Programs\Python\Python311\Lib\site-packages\django\utils\asyncio.py", line 26, in inner
    return func(*args, **kwargs)
           ^^^^^^^^^^^^^^^^^^^^^
  File "C:\Users\Spero 70\AppData\Local\Programs\Python\Python311\Lib\site-packages\django\db\backends\base\base.py", line 278, in ensure_connection
    with self.wrap_database_errors:
  File "C:\Users\Spero 70\AppData\Local\Programs\Python\Python311\Lib\site-packages\django\db\utils.py", line 91, in __exit__
    raise dj_exc_value.with_traceback(traceback) from exc_value
  File "C:\Users\Spero 70\AppData\Local\Programs\Python\Python311\Lib\site-packages\django\db\backends\base\base.py", line 279, in ensure_connection
    self.connect()
  File "C:\Users\Spero 70\AppData\Local\Programs\Python\Python311\Lib\site-packages\django\utils\asyncio.py", line 26, in inner
    return func(*args, **kwargs)
           ^^^^^^^^^^^^^^^^^^^^^
  File "C:\Users\Spero 70\AppData\Local\Programs\Python\Python311\Lib\site-packages\django\db\backends\base\base.py", line 256, in connect
    self.connection = self.get_new_connection(conn_params)
                      ^^^^^^^^^^^^^^^^^^^^^^^^^^^^^^^^^^^^
  File "C:\Users\Spero 70\AppData\Local\Programs\Python\Python311\Lib\site-packages\django\utils\asyncio.py", line 26, in inner
    return func(*args, **kwargs)
           ^^^^^^^^^^^^^^^^^^^^^
  File "C:\Users\Spero 70\AppData\Local\Programs\Python\Python311\Lib\site-packages\django\db\backends\postgresql\base.py", line 332, in get_new_connection
    connection = self.Database.connect(**conn_params)
                 ^^^^^^^^^^^^^^^^^^^^^^^^^^^^^^^^^^^^
  File "C:\Users\Spero 70\AppData\Local\Programs\Python\Python311\Lib\site-packages\psycopg2\__init__.py", line 122, in connect
    conn = _connect(dsn, connection_factory=connection_factory, **kwasync)
           ^^^^^^^^^^^^^^^^^^^^^^^^^^^^^^^^^^^^^^^^^^^^^^^^^^^^^^^^^^^^^^^
django.db.utils.OperationalError: connection to server at "122.176.232.35", port 5433 failed: FATAL:  sorry, too many clients already
connection to server at "122.176.232.35", port 5433 failed: FATAL:  sorry, too many clients already

ERROR 2025-05-16 14:47:51,412 basehttp "GET /admin_web/state_get/ HTTP/1.1" 500 210109
WARNING 2025-05-16 14:57:16,179 log Bad Request: /admin_web/logout/
WARNING 2025-05-16 14:57:16,179 basehttp "POST /admin_web/logout/ HTTP/1.1" 400 37
WARNING 2025-05-16 14:57:17,909 log Unauthorized: /admin_web/district_get/
WARNING 2025-05-16 14:57:17,910 log Unauthorized: /admin_web/Tahsil_get/
WARNING 2025-05-16 14:57:17,916 basehttp "GET /admin_web/district_get/ HTTP/1.1" 401 172
WARNING 2025-05-16 14:57:17,926 basehttp "GET /admin_web/Tahsil_get/ HTTP/1.1" 401 172
WARNING 2025-05-16 14:57:17,933 log Unauthorized: /admin_web/district_get/
WARNING 2025-05-16 14:57:17,938 log Unauthorized: /admin_web/Tahsil_get/
WARNING 2025-05-16 14:57:17,941 basehttp "GET /admin_web/district_get/ HTTP/1.1" 401 172
WARNING 2025-05-16 14:57:17,945 basehttp "GET /admin_web/Tahsil_get/ HTTP/1.1" 401 172
WARNING 2025-05-16 15:21:19,160 log Not Found: /admin_web/district_get_idwise/
WARNING 2025-05-16 15:21:19,160 basehttp "GET /admin_web/district_get_idwise/ HTTP/1.1" 404 11926
WARNING 2025-05-16 15:21:23,496 log Not Found: /admin_web/district_get_idwise
WARNING 2025-05-16 15:21:23,496 basehttp "GET /admin_web/district_get_idwise HTTP/1.1" 404 11923
WARNING 2025-05-16 15:49:29,519 log Unauthorized: /admin_web/district_get/
WARNING 2025-05-16 15:49:29,523 log Unauthorized: /admin_web/Tahsil_get/
WARNING 2025-05-16 15:49:29,524 basehttp "GET /admin_web/district_get/ HTTP/1.1" 401 172
WARNING 2025-05-16 15:49:29,528 basehttp "GET /admin_web/Tahsil_get/ HTTP/1.1" 401 172
WARNING 2025-05-16 15:49:29,536 log Unauthorized: /admin_web/district_get/
WARNING 2025-05-16 15:49:29,538 basehttp "GET /admin_web/district_get/ HTTP/1.1" 401 172
WARNING 2025-05-16 15:49:29,542 log Unauthorized: /admin_web/Tahsil_get/
WARNING 2025-05-16 15:49:29,543 basehttp "GET /admin_web/Tahsil_get/ HTTP/1.1" 401 172
WARNING 2025-05-16 16:11:18,801 log Unauthorized: /admin_web/district_get/
WARNING 2025-05-16 16:11:18,804 log Unauthorized: /admin_web/Tahsil_get/
WARNING 2025-05-16 16:11:18,805 basehttp "GET /admin_web/district_get/ HTTP/1.1" 401 172
WARNING 2025-05-16 16:11:18,805 basehttp "GET /admin_web/Tahsil_get/ HTTP/1.1" 401 172
WARNING 2025-05-16 16:11:18,809 log Unauthorized: /admin_web/district_get/
WARNING 2025-05-16 16:11:18,812 log Unauthorized: /admin_web/Tahsil_get/
WARNING 2025-05-16 16:11:18,812 basehttp "GET /admin_web/district_get/ HTTP/1.1" 401 172
WARNING 2025-05-16 16:11:18,812 basehttp "GET /admin_web/Tahsil_get/ HTTP/1.1" 401 172
WARNING 2025-05-16 16:11:40,201 log Bad Request: /admin_web/login/
WARNING 2025-05-16 16:11:40,201 basehttp "POST /admin_web/login/ HTTP/1.1" 400 54
WARNING 2025-05-16 16:19:08,424 log Unauthorized: /admin_web/district_get_idwise/1/
WARNING 2025-05-16 16:19:08,424 basehttp "GET /admin_web/district_get_idwise/1/ HTTP/1.1" 401 58
WARNING 2025-05-16 16:19:24,252 log Unauthorized: /admin_web/district_get_idwise/1/
WARNING 2025-05-16 16:19:24,252 basehttp "GET /admin_web/district_get_idwise/1/ HTTP/1.1" 401 172
