ERROR 2025-05-15 10:59:43,292 log Internal Server Error: /admin/admin_web/dms_group/
Traceback (most recent call last):
  File "C:\Users\admin\AppData\Roaming\Python\Python311\site-packages\django\db\backends\utils.py", line 105, in _execute
    return self.cursor.execute(sql, params)
           ^^^^^^^^^^^^^^^^^^^^^^^^^^^^^^^^
psycopg2.errors.UndefinedColumn: column admin_web_dms_employee.grp_id_id does not exist
LINE 1: ...mp_doj", "admin_web_dms_employee"."emp_is_login", "admin_web...
                                                             ^
HINT:  Perhaps you meant to reference the column "admin_web_dms_employee.grp_id".


The above exception was the direct cause of the following exception:

Traceback (most recent call last):
  File "C:\Users\admin\AppData\Roaming\Python\Python311\site-packages\django\core\handlers\exception.py", line 55, in inner
    response = get_response(request)
               ^^^^^^^^^^^^^^^^^^^^^
  File "C:\Users\admin\AppData\Roaming\Python\Python311\site-packages\django\core\handlers\base.py", line 197, in _get_response
    response = wrapped_callback(request, *callback_args, **callback_kwargs)
               ^^^^^^^^^^^^^^^^^^^^^^^^^^^^^^^^^^^^^^^^^^^^^^^^^^^^^^^^^^^^
  File "C:\Users\admin\AppData\Roaming\Python\Python311\site-packages\django\contrib\admin\options.py", line 716, in wrapper
    return self.admin_site.admin_view(view)(*args, **kwargs)
           ^^^^^^^^^^^^^^^^^^^^^^^^^^^^^^^^^^^^^^^^^^^^^^^^^
  File "C:\Users\admin\AppData\Roaming\Python\Python311\site-packages\django\utils\decorators.py", line 188, in _view_wrapper
    result = _process_exception(request, e)
             ^^^^^^^^^^^^^^^^^^^^^^^^^^^^^^
  File "C:\Users\admin\AppData\Roaming\Python\Python311\site-packages\django\utils\decorators.py", line 186, in _view_wrapper
    response = view_func(request, *args, **kwargs)
               ^^^^^^^^^^^^^^^^^^^^^^^^^^^^^^^^^^^
  File "C:\Users\admin\AppData\Roaming\Python\Python311\site-packages\django\views\decorators\cache.py", line 80, in _view_wrapper
    response = view_func(request, *args, **kwargs)
               ^^^^^^^^^^^^^^^^^^^^^^^^^^^^^^^^^^^
  File "C:\Users\admin\AppData\Roaming\Python\Python311\site-packages\django\contrib\admin\sites.py", line 228, in inner
    if not self.has_permission(request):
           ^^^^^^^^^^^^^^^^^^^^^^^^^^^^
  File "C:\Users\admin\AppData\Roaming\Python\Python311\site-packages\django\contrib\admin\sites.py", line 201, in has_permission
    return request.user.is_active and request.user.is_staff
           ^^^^^^^^^^^^^^^^^^^^^^
  File "C:\Users\admin\AppData\Roaming\Python\Python311\site-packages\django\utils\functional.py", line 251, in inner
    self._setup()
  File "C:\Users\admin\AppData\Roaming\Python\Python311\site-packages\django\utils\functional.py", line 404, in _setup
    self._wrapped = self._setupfunc()
                    ^^^^^^^^^^^^^^^^^
  File "C:\Users\admin\AppData\Roaming\Python\Python311\site-packages\django\contrib\auth\middleware.py", line 33, in <lambda>
    request.user = SimpleLazyObject(lambda: get_user(request))
                                            ^^^^^^^^^^^^^^^^^
  File "C:\Users\admin\AppData\Roaming\Python\Python311\site-packages\django\contrib\auth\middleware.py", line 13, in get_user
    request._cached_user = auth.get_user(request)
                           ^^^^^^^^^^^^^^^^^^^^^^
  File "C:\Users\admin\AppData\Roaming\Python\Python311\site-packages\django\contrib\auth\__init__.py", line 216, in get_user
    user = backend.get_user(user_id)
           ^^^^^^^^^^^^^^^^^^^^^^^^^
  File "C:\Users\admin\AppData\Roaming\Python\Python311\site-packages\django\contrib\auth\backends.py", line 157, in get_user
    user = UserModel._default_manager.get(pk=user_id)
           ^^^^^^^^^^^^^^^^^^^^^^^^^^^^^^^^^^^^^^^^^^
  File "C:\Users\admin\AppData\Roaming\Python\Python311\site-packages\django\db\models\manager.py", line 87, in manager_method
    return getattr(self.get_queryset(), name)(*args, **kwargs)
           ^^^^^^^^^^^^^^^^^^^^^^^^^^^^^^^^^^^^^^^^^^^^^^^^^^^
  File "C:\Users\admin\AppData\Roaming\Python\Python311\site-packages\django\db\models\query.py", line 645, in get
    num = len(clone)
          ^^^^^^^^^^
  File "C:\Users\admin\AppData\Roaming\Python\Python311\site-packages\django\db\models\query.py", line 382, in __len__
    self._fetch_all()
  File "C:\Users\admin\AppData\Roaming\Python\Python311\site-packages\django\db\models\query.py", line 1928, in _fetch_all
    self._result_cache = list(self._iterable_class(self))
                         ^^^^^^^^^^^^^^^^^^^^^^^^^^^^^^^^
  File "C:\Users\admin\AppData\Roaming\Python\Python311\site-packages\django\db\models\query.py", line 91, in __iter__
    results = compiler.execute_sql(
              ^^^^^^^^^^^^^^^^^^^^^
  File "C:\Users\admin\AppData\Roaming\Python\Python311\site-packages\django\db\models\sql\compiler.py", line 1562, in execute_sql
    cursor.execute(sql, params)
  File "C:\Users\admin\AppData\Roaming\Python\Python311\site-packages\django\db\backends\utils.py", line 122, in execute
    return super().execute(sql, params)
           ^^^^^^^^^^^^^^^^^^^^^^^^^^^^
  File "C:\Users\admin\AppData\Roaming\Python\Python311\site-packages\django\db\backends\utils.py", line 79, in execute
    return self._execute_with_wrappers(
           ^^^^^^^^^^^^^^^^^^^^^^^^^^^^
  File "C:\Users\admin\AppData\Roaming\Python\Python311\site-packages\django\db\backends\utils.py", line 92, in _execute_with_wrappers
    return executor(sql, params, many, context)
           ^^^^^^^^^^^^^^^^^^^^^^^^^^^^^^^^^^^^
  File "C:\Users\admin\AppData\Roaming\Python\Python311\site-packages\django\db\backends\utils.py", line 100, in _execute
    with self.db.wrap_database_errors:
  File "C:\Users\admin\AppData\Roaming\Python\Python311\site-packages\django\db\utils.py", line 91, in __exit__
    raise dj_exc_value.with_traceback(traceback) from exc_value
  File "C:\Users\admin\AppData\Roaming\Python\Python311\site-packages\django\db\backends\utils.py", line 105, in _execute
    return self.cursor.execute(sql, params)
           ^^^^^^^^^^^^^^^^^^^^^^^^^^^^^^^^
django.db.utils.ProgrammingError: column admin_web_dms_employee.grp_id_id does not exist
LINE 1: ...mp_doj", "admin_web_dms_employee"."emp_is_login", "admin_web...
                                                             ^
HINT:  Perhaps you meant to reference the column "admin_web_dms_employee.grp_id".

ERROR 2025-05-15 10:59:43,310 basehttp "GET /admin/admin_web/dms_group/ HTTP/1.1" 500 192995
WARNING 2025-05-16 10:44:10,160 log Not Found: /
WARNING 2025-05-16 10:44:10,161 basehttp "GET / HTTP/1.1" 404 2278
WARNING 2025-05-16 10:44:10,358 log Not Found: /favicon.ico
WARNING 2025-05-16 10:44:10,359 basehttp "GET /favicon.ico HTTP/1.1" 404 2329
